[Errno 32] Broken pipe
['multiprocessing.pool.RemoteTraceback: \n"""\nTraceback (most recent call last):\n  File "/home/ubuntu/Desktop/inzz/quad_cross/quad_learn_1.py", line 246, in run_sim\n    result = sim(genome, config, rou)\n  File "/home/ubuntu/Desktop/inzz/quad_cross/quad_learn_1.py", line 94, in sim\n    traci.start([sumoBinary,  "--no-warnings", "-c", filename,\n  File "/home/ubuntu/.local/lib/python3.10/site-packages/traci/main.py", line 147, in start\n    result = init(sumoPort, numRetries, "localhost", label, sumoProcess, doSwitch, traceFile, traceGetters)\n  File "/home/ubuntu/.local/lib/python3.10/site-packages/traci/main.py", line 119, in init\n    return con.getVersion()\n  File "/home/ubuntu/.local/lib/python3.10/site-packages/traci/connection.py", line 381, in getVersion\n    result = self._sendCmd(command, None, None)\n  File "/home/ubuntu/.local/lib/python3.10/site-packages/traci/connection.py", line 231, in _sendCmd\n    return self._sendExact()\n  File "/home/ubuntu/.local/lib/python3.10/site-packages/traci/connection.py", line 130, in _sendExact\n    self._socket.send(length + self._string)\nConnectionResetError: [Errno 104] Connection reset by peer\n\nDuring handling of the above exception, another exception occurred:\n\nTraceback (most recent call last):\n  File "/home/ubuntu/Desktop/inzz/quad_cross/quad_learn_1.py", line 253, in run_sim\n    result = sim(genome, config, rou)\n  File "/home/ubuntu/Desktop/inzz/quad_cross/quad_learn_1.py", line 94, in sim\n    traci.start([sumoBinary,  "--no-warnings", "-c", filename,\n  File "/home/ubuntu/.local/lib/python3.10/site-packages/traci/main.py", line 139, in start\n    raise TraCIException("Connection \'%s\' is already active." % label)\ntraci.exceptions.TraCIException: Connection \'default\' is already active.\n\nDuring handling of the above exception, another exception occurred:\n\nTraceback (most recent call last):\n  File "/home/ubuntu/Desktop/inzz/quad_cross/quad_learn_1.py", line 260, in run_sim\n    result = sim(genome, config, rou)\n  File "/home/ubuntu/Desktop/inzz/quad_cross/quad_learn_1.py", line 94, in sim\n    traci.start([sumoBinary,  "--no-warnings", "-c", filename,\n  File "/home/ubuntu/.local/lib/python3.10/site-packages/traci/main.py", line 139, in start\n    raise TraCIException("Connection \'%s\' is already active." % label)\ntraci.exceptions.TraCIException: Connection \'default\' is already active.\n\nDuring handling of the above exception, another exception occurred:\n\nTraceback (most recent call last):\n  File "/home/ubuntu/Desktop/inzz/quad_cross/quad_learn_1.py", line 267, in run_sim\n    result = sim(genome, config, rou)\n  File "/home/ubuntu/Desktop/inzz/quad_cross/quad_learn_1.py", line 94, in sim\n    traci.start([sumoBinary,  "--no-warnings", "-c", filename,\n  File "/home/ubuntu/.local/lib/python3.10/site-packages/traci/main.py", line 139, in start\n    raise TraCIException("Connection \'%s\' is already active." % label)\ntraci.exceptions.TraCIException: Connection \'default\' is already active.\n\nDuring handling of the above exception, another exception occurred:\n\nTraceback (most recent call last):\n  File "/usr/lib/python3.10/multiprocessing/pool.py", line 125, in worker\n    result = (True, func(*args, **kwds))\n  File "/home/ubuntu/Desktop/inzz/quad_cross/quad_learn_1.py", line 277, in eval_genome\n    fitness_1 = run_sim(genome, config, "_1")\n  File "/home/ubuntu/Desktop/inzz/quad_cross/quad_learn_1.py", line 273, in run_sim\n    traci.close()\n  File "/home/ubuntu/.local/lib/python3.10/site-packages/traci/main.py", line 262, in close\n    connection.check().close(wait)\n  File "/home/ubuntu/.local/lib/python3.10/site-packages/traci/connection.py", line 396, in close\n    self._sendCmd(tc.CMD_CLOSE, None, None)\n  File "/home/ubuntu/.local/lib/python3.10/site-packages/traci/connection.py", line 231, in _sendCmd\n    return self._sendExact()\n  File "/home/ubuntu/.local/lib/python3.10/site-packages/traci/connection.py", line 130, in _sendExact\n    self._socket.send(length + self._string)\nBrokenPipeError: [Errno 32] Broken pipe\n"""\n', '\nThe above exception was the direct cause of the following exception:\n\n', 'Traceback (most recent call last):\n', '  File "/home/ubuntu/Desktop/inzz/quad_cross/quad_learn_1.py", line 322, in learn\n    winner = pop.run(pe.evaluate, generations)\n', '  File "/home/ubuntu/.local/lib/python3.10/site-packages/neat/population.py", line 89, in run\n    fitness_function(list(iteritems(self.population)), self.config)\n', '  File "/home/ubuntu/.local/lib/python3.10/site-packages/neat/parallel.py", line 30, in evaluate\n    genome.fitness = job.get(timeout=self.timeout)\n', '  File "/usr/lib/python3.10/multiprocessing/pool.py", line 774, in get\n    raise self._value\n', 'BrokenPipeError: [Errno 32] Broken pipe\n']

-818.32242,3081,VehicleNumber,2_pop_175_data_VehicleNumber
-1285.05,3339,VehicleNumber,3_pop_175_data_VehicleNumber
-1053.78225,4372,VehicleNumberAndHaltingNumber,1_pop_175_data_VehicleNumberAndHaltingNumber
-1400.03,4583,VehicleNumberAndHaltingNumber,2_pop_175_data_VehicleNumberAndHaltingNumber
-619.35301,6091,VehicleNumberAndHaltingNumber,3_pop_175_data_VehicleNumberAndHaltingNumber
-1288.71,6310,All,1_pop_175_data_All
-1033.8626900000002,6251,All,2_pop_175_data_All
-967.4423300000001,6075,All,3_pop_175_data_All
