failed to execute PosixPath('dot'), make sure the Graphviz executables are on your systems' PATH
['Traceback (most recent call last):\n', '  File "/home/sosna/.local/lib/python3.12/site-packages/graphviz/backend/execute.py", line 78, in run_check\n    proc = subprocess.run(cmd, **kwargs)\n           ^^^^^^^^^^^^^^^^^^^^^^^^^^^^^\n', '  File "/usr/lib/python3.12/subprocess.py", line 548, in run\n    with Popen(*popenargs, **kwargs) as process:\n         ^^^^^^^^^^^^^^^^^^^^^^^^^^^\n', '  File "/usr/lib/python3.12/subprocess.py", line 1026, in __init__\n    self._execute_child(args, executable, preexec_fn, close_fds,\n', '  File "/usr/lib/python3.12/subprocess.py", line 1955, in _execute_child\n    raise child_exception_type(errno_num, err_msg, err_filename)\n', "FileNotFoundError: [Errno 2] No such file or directory: PosixPath('dot')\n", '\nThe above exception was the direct cause of the following exception:\n\n', 'Traceback (most recent call last):\n', '  File "/home/sosna/inzz/tempp/quad_cross/quad_learn_2.py", line 426, in learn\n    visualize.draw_net(config, winner, view=False, filename=os.path.join(\n', '  File "/home/sosna/inzz/tempp/quad_cross/visualize.py", line 182, in draw_net\n    dot.render(filename, view=view)\n', '  File "/home/sosna/.local/lib/python3.12/site-packages/graphviz/_tools.py", line 171, in wrapper\n    return func(*args, **kwargs)\n           ^^^^^^^^^^^^^^^^^^^^^\n', '  File "/home/sosna/.local/lib/python3.12/site-packages/graphviz/rendering.py", line 122, in render\n    rendered = self._render(*args, **kwargs)\n               ^^^^^^^^^^^^^^^^^^^^^^^^^^^^^\n', '  File "/home/sosna/.local/lib/python3.12/site-packages/graphviz/_tools.py", line 171, in wrapper\n    return func(*args, **kwargs)\n           ^^^^^^^^^^^^^^^^^^^^^\n', '  File "/home/sosna/.local/lib/python3.12/site-packages/graphviz/backend/rendering.py", line 326, in render\n    execute.run_check(cmd,\n', '  File "/home/sosna/.local/lib/python3.12/site-packages/graphviz/backend/execute.py", line 81, in run_check\n    raise ExecutableNotFound(cmd) from e\n', "graphviz.backend.execute.ExecutableNotFound: failed to execute PosixPath('dot'), make sure the Graphviz executables are on your systems' PATH\n"]

failed to execute PosixPath('dot'), make sure the Graphviz executables are on your systems' PATH
['Traceback (most recent call last):\n', '  File "/home/sosna/.local/lib/python3.12/site-packages/graphviz/backend/execute.py", line 78, in run_check\n    proc = subprocess.run(cmd, **kwargs)\n           ^^^^^^^^^^^^^^^^^^^^^^^^^^^^^\n', '  File "/usr/lib/python3.12/subprocess.py", line 548, in run\n    with Popen(*popenargs, **kwargs) as process:\n         ^^^^^^^^^^^^^^^^^^^^^^^^^^^\n', '  File "/usr/lib/python3.12/subprocess.py", line 1026, in __init__\n    self._execute_child(args, executable, preexec_fn, close_fds,\n', '  File "/usr/lib/python3.12/subprocess.py", line 1955, in _execute_child\n    raise child_exception_type(errno_num, err_msg, err_filename)\n', "FileNotFoundError: [Errno 2] No such file or directory: PosixPath('dot')\n", '\nThe above exception was the direct cause of the following exception:\n\n', 'Traceback (most recent call last):\n', '  File "/home/sosna/inzz/tempp/quad_cross/quad_learn_2.py", line 426, in learn\n    visualize.draw_net(config, winner, view=False, filename=os.path.join(\n', '  File "/home/sosna/inzz/tempp/quad_cross/visualize.py", line 182, in draw_net\n    dot.render(filename, view=view)\n', '  File "/home/sosna/.local/lib/python3.12/site-packages/graphviz/_tools.py", line 171, in wrapper\n    return func(*args, **kwargs)\n           ^^^^^^^^^^^^^^^^^^^^^\n', '  File "/home/sosna/.local/lib/python3.12/site-packages/graphviz/rendering.py", line 122, in render\n    rendered = self._render(*args, **kwargs)\n               ^^^^^^^^^^^^^^^^^^^^^^^^^^^^^\n', '  File "/home/sosna/.local/lib/python3.12/site-packages/graphviz/_tools.py", line 171, in wrapper\n    return func(*args, **kwargs)\n           ^^^^^^^^^^^^^^^^^^^^^\n', '  File "/home/sosna/.local/lib/python3.12/site-packages/graphviz/backend/rendering.py", line 326, in render\n    execute.run_check(cmd,\n', '  File "/home/sosna/.local/lib/python3.12/site-packages/graphviz/backend/execute.py", line 81, in run_check\n    raise ExecutableNotFound(cmd) from e\n', "graphviz.backend.execute.ExecutableNotFound: failed to execute PosixPath('dot'), make sure the Graphviz executables are on your systems' PATH\n"]

failed to execute PosixPath('dot'), make sure the Graphviz executables are on your systems' PATH
['Traceback (most recent call last):\n', '  File "/home/sosna/.local/lib/python3.12/site-packages/graphviz/backend/execute.py", line 78, in run_check\n    proc = subprocess.run(cmd, **kwargs)\n           ^^^^^^^^^^^^^^^^^^^^^^^^^^^^^\n', '  File "/usr/lib/python3.12/subprocess.py", line 548, in run\n    with Popen(*popenargs, **kwargs) as process:\n         ^^^^^^^^^^^^^^^^^^^^^^^^^^^\n', '  File "/usr/lib/python3.12/subprocess.py", line 1026, in __init__\n    self._execute_child(args, executable, preexec_fn, close_fds,\n', '  File "/usr/lib/python3.12/subprocess.py", line 1955, in _execute_child\n    raise child_exception_type(errno_num, err_msg, err_filename)\n', "FileNotFoundError: [Errno 2] No such file or directory: PosixPath('dot')\n", '\nThe above exception was the direct cause of the following exception:\n\n', 'Traceback (most recent call last):\n', '  File "/home/sosna/inzz/tempp/quad_cross/quad_learn_2.py", line 426, in learn\n    visualize.draw_net(config, winner, view=False, filename=os.path.join(\n', '  File "/home/sosna/inzz/tempp/quad_cross/visualize.py", line 182, in draw_net\n    dot.render(filename, view=view)\n', '  File "/home/sosna/.local/lib/python3.12/site-packages/graphviz/_tools.py", line 171, in wrapper\n    return func(*args, **kwargs)\n           ^^^^^^^^^^^^^^^^^^^^^\n', '  File "/home/sosna/.local/lib/python3.12/site-packages/graphviz/rendering.py", line 122, in render\n    rendered = self._render(*args, **kwargs)\n               ^^^^^^^^^^^^^^^^^^^^^^^^^^^^^\n', '  File "/home/sosna/.local/lib/python3.12/site-packages/graphviz/_tools.py", line 171, in wrapper\n    return func(*args, **kwargs)\n           ^^^^^^^^^^^^^^^^^^^^^\n', '  File "/home/sosna/.local/lib/python3.12/site-packages/graphviz/backend/rendering.py", line 326, in render\n    execute.run_check(cmd,\n', '  File "/home/sosna/.local/lib/python3.12/site-packages/graphviz/backend/execute.py", line 81, in run_check\n    raise ExecutableNotFound(cmd) from e\n', "graphviz.backend.execute.ExecutableNotFound: failed to execute PosixPath('dot'), make sure the Graphviz executables are on your systems' PATH\n"]

failed to execute PosixPath('dot'), make sure the Graphviz executables are on your systems' PATH
['Traceback (most recent call last):\n', '  File "/home/sosna/.local/lib/python3.12/site-packages/graphviz/backend/execute.py", line 78, in run_check\n    proc = subprocess.run(cmd, **kwargs)\n           ^^^^^^^^^^^^^^^^^^^^^^^^^^^^^\n', '  File "/usr/lib/python3.12/subprocess.py", line 548, in run\n    with Popen(*popenargs, **kwargs) as process:\n         ^^^^^^^^^^^^^^^^^^^^^^^^^^^\n', '  File "/usr/lib/python3.12/subprocess.py", line 1026, in __init__\n    self._execute_child(args, executable, preexec_fn, close_fds,\n', '  File "/usr/lib/python3.12/subprocess.py", line 1955, in _execute_child\n    raise child_exception_type(errno_num, err_msg, err_filename)\n', "FileNotFoundError: [Errno 2] No such file or directory: PosixPath('dot')\n", '\nThe above exception was the direct cause of the following exception:\n\n', 'Traceback (most recent call last):\n', '  File "/home/sosna/inzz/tempp/quad_cross/quad_learn_2.py", line 426, in learn\n    visualize.draw_net(config, winner, view=False, filename=os.path.join(\n', '  File "/home/sosna/inzz/tempp/quad_cross/visualize.py", line 182, in draw_net\n    dot.render(filename, view=view)\n', '  File "/home/sosna/.local/lib/python3.12/site-packages/graphviz/_tools.py", line 171, in wrapper\n    return func(*args, **kwargs)\n           ^^^^^^^^^^^^^^^^^^^^^\n', '  File "/home/sosna/.local/lib/python3.12/site-packages/graphviz/rendering.py", line 122, in render\n    rendered = self._render(*args, **kwargs)\n               ^^^^^^^^^^^^^^^^^^^^^^^^^^^^^\n', '  File "/home/sosna/.local/lib/python3.12/site-packages/graphviz/_tools.py", line 171, in wrapper\n    return func(*args, **kwargs)\n           ^^^^^^^^^^^^^^^^^^^^^\n', '  File "/home/sosna/.local/lib/python3.12/site-packages/graphviz/backend/rendering.py", line 326, in render\n    execute.run_check(cmd,\n', '  File "/home/sosna/.local/lib/python3.12/site-packages/graphviz/backend/execute.py", line 81, in run_check\n    raise ExecutableNotFound(cmd) from e\n', "graphviz.backend.execute.ExecutableNotFound: failed to execute PosixPath('dot'), make sure the Graphviz executables are on your systems' PATH\n"]

failed to execute PosixPath('dot'), make sure the Graphviz executables are on your systems' PATH
['Traceback (most recent call last):\n', '  File "/home/sosna/.local/lib/python3.12/site-packages/graphviz/backend/execute.py", line 78, in run_check\n    proc = subprocess.run(cmd, **kwargs)\n           ^^^^^^^^^^^^^^^^^^^^^^^^^^^^^\n', '  File "/usr/lib/python3.12/subprocess.py", line 548, in run\n    with Popen(*popenargs, **kwargs) as process:\n         ^^^^^^^^^^^^^^^^^^^^^^^^^^^\n', '  File "/usr/lib/python3.12/subprocess.py", line 1026, in __init__\n    self._execute_child(args, executable, preexec_fn, close_fds,\n', '  File "/usr/lib/python3.12/subprocess.py", line 1955, in _execute_child\n    raise child_exception_type(errno_num, err_msg, err_filename)\n', "FileNotFoundError: [Errno 2] No such file or directory: PosixPath('dot')\n", '\nThe above exception was the direct cause of the following exception:\n\n', 'Traceback (most recent call last):\n', '  File "/home/sosna/inzz/tempp/quad_cross/quad_learn_2.py", line 426, in learn\n    visualize.draw_net(config, winner, view=False, filename=os.path.join(\n', '  File "/home/sosna/inzz/tempp/quad_cross/visualize.py", line 182, in draw_net\n    dot.render(filename, view=view)\n', '  File "/home/sosna/.local/lib/python3.12/site-packages/graphviz/_tools.py", line 171, in wrapper\n    return func(*args, **kwargs)\n           ^^^^^^^^^^^^^^^^^^^^^\n', '  File "/home/sosna/.local/lib/python3.12/site-packages/graphviz/rendering.py", line 122, in render\n    rendered = self._render(*args, **kwargs)\n               ^^^^^^^^^^^^^^^^^^^^^^^^^^^^^\n', '  File "/home/sosna/.local/lib/python3.12/site-packages/graphviz/_tools.py", line 171, in wrapper\n    return func(*args, **kwargs)\n           ^^^^^^^^^^^^^^^^^^^^^\n', '  File "/home/sosna/.local/lib/python3.12/site-packages/graphviz/backend/rendering.py", line 326, in render\n    execute.run_check(cmd,\n', '  File "/home/sosna/.local/lib/python3.12/site-packages/graphviz/backend/execute.py", line 81, in run_check\n    raise ExecutableNotFound(cmd) from e\n', "graphviz.backend.execute.ExecutableNotFound: failed to execute PosixPath('dot'), make sure the Graphviz executables are on your systems' PATH\n"]

failed to execute PosixPath('dot'), make sure the Graphviz executables are on your systems' PATH
['Traceback (most recent call last):\n', '  File "/home/sosna/.local/lib/python3.12/site-packages/graphviz/backend/execute.py", line 78, in run_check\n    proc = subprocess.run(cmd, **kwargs)\n           ^^^^^^^^^^^^^^^^^^^^^^^^^^^^^\n', '  File "/usr/lib/python3.12/subprocess.py", line 548, in run\n    with Popen(*popenargs, **kwargs) as process:\n         ^^^^^^^^^^^^^^^^^^^^^^^^^^^\n', '  File "/usr/lib/python3.12/subprocess.py", line 1026, in __init__\n    self._execute_child(args, executable, preexec_fn, close_fds,\n', '  File "/usr/lib/python3.12/subprocess.py", line 1955, in _execute_child\n    raise child_exception_type(errno_num, err_msg, err_filename)\n', "FileNotFoundError: [Errno 2] No such file or directory: PosixPath('dot')\n", '\nThe above exception was the direct cause of the following exception:\n\n', 'Traceback (most recent call last):\n', '  File "/home/sosna/inzz/tempp/quad_cross/quad_learn_2.py", line 426, in learn\n    visualize.draw_net(config, winner, view=False, filename=os.path.join(\n', '  File "/home/sosna/inzz/tempp/quad_cross/visualize.py", line 182, in draw_net\n    dot.render(filename, view=view)\n', '  File "/home/sosna/.local/lib/python3.12/site-packages/graphviz/_tools.py", line 171, in wrapper\n    return func(*args, **kwargs)\n           ^^^^^^^^^^^^^^^^^^^^^\n', '  File "/home/sosna/.local/lib/python3.12/site-packages/graphviz/rendering.py", line 122, in render\n    rendered = self._render(*args, **kwargs)\n               ^^^^^^^^^^^^^^^^^^^^^^^^^^^^^\n', '  File "/home/sosna/.local/lib/python3.12/site-packages/graphviz/_tools.py", line 171, in wrapper\n    return func(*args, **kwargs)\n           ^^^^^^^^^^^^^^^^^^^^^\n', '  File "/home/sosna/.local/lib/python3.12/site-packages/graphviz/backend/rendering.py", line 326, in render\n    execute.run_check(cmd,\n', '  File "/home/sosna/.local/lib/python3.12/site-packages/graphviz/backend/execute.py", line 81, in run_check\n    raise ExecutableNotFound(cmd) from e\n', "graphviz.backend.execute.ExecutableNotFound: failed to execute PosixPath('dot'), make sure the Graphviz executables are on your systems' PATH\n"]

failed to execute PosixPath('dot'), make sure the Graphviz executables are on your systems' PATH
['Traceback (most recent call last):\n', '  File "/home/sosna/.local/lib/python3.12/site-packages/graphviz/backend/execute.py", line 78, in run_check\n    proc = subprocess.run(cmd, **kwargs)\n           ^^^^^^^^^^^^^^^^^^^^^^^^^^^^^\n', '  File "/usr/lib/python3.12/subprocess.py", line 548, in run\n    with Popen(*popenargs, **kwargs) as process:\n         ^^^^^^^^^^^^^^^^^^^^^^^^^^^\n', '  File "/usr/lib/python3.12/subprocess.py", line 1026, in __init__\n    self._execute_child(args, executable, preexec_fn, close_fds,\n', '  File "/usr/lib/python3.12/subprocess.py", line 1955, in _execute_child\n    raise child_exception_type(errno_num, err_msg, err_filename)\n', "FileNotFoundError: [Errno 2] No such file or directory: PosixPath('dot')\n", '\nThe above exception was the direct cause of the following exception:\n\n', 'Traceback (most recent call last):\n', '  File "/home/sosna/inzz/tempp/quad_cross/quad_learn_2.py", line 426, in learn\n    visualize.draw_net(config, winner, view=False, filename=os.path.join(\n', '  File "/home/sosna/inzz/tempp/quad_cross/visualize.py", line 182, in draw_net\n    dot.render(filename, view=view)\n', '  File "/home/sosna/.local/lib/python3.12/site-packages/graphviz/_tools.py", line 171, in wrapper\n    return func(*args, **kwargs)\n           ^^^^^^^^^^^^^^^^^^^^^\n', '  File "/home/sosna/.local/lib/python3.12/site-packages/graphviz/rendering.py", line 122, in render\n    rendered = self._render(*args, **kwargs)\n               ^^^^^^^^^^^^^^^^^^^^^^^^^^^^^\n', '  File "/home/sosna/.local/lib/python3.12/site-packages/graphviz/_tools.py", line 171, in wrapper\n    return func(*args, **kwargs)\n           ^^^^^^^^^^^^^^^^^^^^^\n', '  File "/home/sosna/.local/lib/python3.12/site-packages/graphviz/backend/rendering.py", line 326, in render\n    execute.run_check(cmd,\n', '  File "/home/sosna/.local/lib/python3.12/site-packages/graphviz/backend/execute.py", line 81, in run_check\n    raise ExecutableNotFound(cmd) from e\n', "graphviz.backend.execute.ExecutableNotFound: failed to execute PosixPath('dot'), make sure the Graphviz executables are on your systems' PATH\n"]

failed to execute PosixPath('dot'), make sure the Graphviz executables are on your systems' PATH
['Traceback (most recent call last):\n', '  File "/home/sosna/.local/lib/python3.12/site-packages/graphviz/backend/execute.py", line 78, in run_check\n    proc = subprocess.run(cmd, **kwargs)\n           ^^^^^^^^^^^^^^^^^^^^^^^^^^^^^\n', '  File "/usr/lib/python3.12/subprocess.py", line 548, in run\n    with Popen(*popenargs, **kwargs) as process:\n         ^^^^^^^^^^^^^^^^^^^^^^^^^^^\n', '  File "/usr/lib/python3.12/subprocess.py", line 1026, in __init__\n    self._execute_child(args, executable, preexec_fn, close_fds,\n', '  File "/usr/lib/python3.12/subprocess.py", line 1955, in _execute_child\n    raise child_exception_type(errno_num, err_msg, err_filename)\n', "FileNotFoundError: [Errno 2] No such file or directory: PosixPath('dot')\n", '\nThe above exception was the direct cause of the following exception:\n\n', 'Traceback (most recent call last):\n', '  File "/home/sosna/inzz/tempp/quad_cross/quad_learn_2.py", line 426, in learn\n    visualize.draw_net(config, winner, view=False, filename=os.path.join(\n', '  File "/home/sosna/inzz/tempp/quad_cross/visualize.py", line 182, in draw_net\n    dot.render(filename, view=view)\n', '  File "/home/sosna/.local/lib/python3.12/site-packages/graphviz/_tools.py", line 171, in wrapper\n    return func(*args, **kwargs)\n           ^^^^^^^^^^^^^^^^^^^^^\n', '  File "/home/sosna/.local/lib/python3.12/site-packages/graphviz/rendering.py", line 122, in render\n    rendered = self._render(*args, **kwargs)\n               ^^^^^^^^^^^^^^^^^^^^^^^^^^^^^\n', '  File "/home/sosna/.local/lib/python3.12/site-packages/graphviz/_tools.py", line 171, in wrapper\n    return func(*args, **kwargs)\n           ^^^^^^^^^^^^^^^^^^^^^\n', '  File "/home/sosna/.local/lib/python3.12/site-packages/graphviz/backend/rendering.py", line 326, in render\n    execute.run_check(cmd,\n', '  File "/home/sosna/.local/lib/python3.12/site-packages/graphviz/backend/execute.py", line 81, in run_check\n    raise ExecutableNotFound(cmd) from e\n', "graphviz.backend.execute.ExecutableNotFound: failed to execute PosixPath('dot'), make sure the Graphviz executables are on your systems' PATH\n"]

failed to execute PosixPath('dot'), make sure the Graphviz executables are on your systems' PATH
['Traceback (most recent call last):\n', '  File "/home/sosna/.local/lib/python3.12/site-packages/graphviz/backend/execute.py", line 78, in run_check\n    proc = subprocess.run(cmd, **kwargs)\n           ^^^^^^^^^^^^^^^^^^^^^^^^^^^^^\n', '  File "/usr/lib/python3.12/subprocess.py", line 548, in run\n    with Popen(*popenargs, **kwargs) as process:\n         ^^^^^^^^^^^^^^^^^^^^^^^^^^^\n', '  File "/usr/lib/python3.12/subprocess.py", line 1026, in __init__\n    self._execute_child(args, executable, preexec_fn, close_fds,\n', '  File "/usr/lib/python3.12/subprocess.py", line 1955, in _execute_child\n    raise child_exception_type(errno_num, err_msg, err_filename)\n', "FileNotFoundError: [Errno 2] No such file or directory: PosixPath('dot')\n", '\nThe above exception was the direct cause of the following exception:\n\n', 'Traceback (most recent call last):\n', '  File "/home/sosna/inzz/tempp/quad_cross/quad_learn_2.py", line 426, in learn\n    visualize.draw_net(config, winner, view=False, filename=os.path.join(\n', '  File "/home/sosna/inzz/tempp/quad_cross/visualize.py", line 182, in draw_net\n    dot.render(filename, view=view)\n', '  File "/home/sosna/.local/lib/python3.12/site-packages/graphviz/_tools.py", line 171, in wrapper\n    return func(*args, **kwargs)\n           ^^^^^^^^^^^^^^^^^^^^^\n', '  File "/home/sosna/.local/lib/python3.12/site-packages/graphviz/rendering.py", line 122, in render\n    rendered = self._render(*args, **kwargs)\n               ^^^^^^^^^^^^^^^^^^^^^^^^^^^^^\n', '  File "/home/sosna/.local/lib/python3.12/site-packages/graphviz/_tools.py", line 171, in wrapper\n    return func(*args, **kwargs)\n           ^^^^^^^^^^^^^^^^^^^^^\n', '  File "/home/sosna/.local/lib/python3.12/site-packages/graphviz/backend/rendering.py", line 326, in render\n    execute.run_check(cmd,\n', '  File "/home/sosna/.local/lib/python3.12/site-packages/graphviz/backend/execute.py", line 81, in run_check\n    raise ExecutableNotFound(cmd) from e\n', "graphviz.backend.execute.ExecutableNotFound: failed to execute PosixPath('dot'), make sure the Graphviz executables are on your systems' PATH\n"]

failed to execute PosixPath('dot'), make sure the Graphviz executables are on your systems' PATH
['Traceback (most recent call last):\n', '  File "/home/sosna/.local/lib/python3.12/site-packages/graphviz/backend/execute.py", line 78, in run_check\n    proc = subprocess.run(cmd, **kwargs)\n           ^^^^^^^^^^^^^^^^^^^^^^^^^^^^^\n', '  File "/usr/lib/python3.12/subprocess.py", line 548, in run\n    with Popen(*popenargs, **kwargs) as process:\n         ^^^^^^^^^^^^^^^^^^^^^^^^^^^\n', '  File "/usr/lib/python3.12/subprocess.py", line 1026, in __init__\n    self._execute_child(args, executable, preexec_fn, close_fds,\n', '  File "/usr/lib/python3.12/subprocess.py", line 1955, in _execute_child\n    raise child_exception_type(errno_num, err_msg, err_filename)\n', "FileNotFoundError: [Errno 2] No such file or directory: PosixPath('dot')\n", '\nThe above exception was the direct cause of the following exception:\n\n', 'Traceback (most recent call last):\n', '  File "/home/sosna/inzz/tempp/quad_cross/quad_learn_2.py", line 426, in learn\n    visualize.draw_net(config, winner, view=False, filename=os.path.join(\n', '  File "/home/sosna/inzz/tempp/quad_cross/visualize.py", line 182, in draw_net\n    dot.render(filename, view=view)\n', '  File "/home/sosna/.local/lib/python3.12/site-packages/graphviz/_tools.py", line 171, in wrapper\n    return func(*args, **kwargs)\n           ^^^^^^^^^^^^^^^^^^^^^\n', '  File "/home/sosna/.local/lib/python3.12/site-packages/graphviz/rendering.py", line 122, in render\n    rendered = self._render(*args, **kwargs)\n               ^^^^^^^^^^^^^^^^^^^^^^^^^^^^^\n', '  File "/home/sosna/.local/lib/python3.12/site-packages/graphviz/_tools.py", line 171, in wrapper\n    return func(*args, **kwargs)\n           ^^^^^^^^^^^^^^^^^^^^^\n', '  File "/home/sosna/.local/lib/python3.12/site-packages/graphviz/backend/rendering.py", line 326, in render\n    execute.run_check(cmd,\n', '  File "/home/sosna/.local/lib/python3.12/site-packages/graphviz/backend/execute.py", line 81, in run_check\n    raise ExecutableNotFound(cmd) from e\n', "graphviz.backend.execute.ExecutableNotFound: failed to execute PosixPath('dot'), make sure the Graphviz executables are on your systems' PATH\n"]

failed to execute PosixPath('dot'), make sure the Graphviz executables are on your systems' PATH
['Traceback (most recent call last):\n', '  File "/home/sosna/.local/lib/python3.12/site-packages/graphviz/backend/execute.py", line 78, in run_check\n    proc = subprocess.run(cmd, **kwargs)\n           ^^^^^^^^^^^^^^^^^^^^^^^^^^^^^\n', '  File "/usr/lib/python3.12/subprocess.py", line 548, in run\n    with Popen(*popenargs, **kwargs) as process:\n         ^^^^^^^^^^^^^^^^^^^^^^^^^^^\n', '  File "/usr/lib/python3.12/subprocess.py", line 1026, in __init__\n    self._execute_child(args, executable, preexec_fn, close_fds,\n', '  File "/usr/lib/python3.12/subprocess.py", line 1955, in _execute_child\n    raise child_exception_type(errno_num, err_msg, err_filename)\n', "FileNotFoundError: [Errno 2] No such file or directory: PosixPath('dot')\n", '\nThe above exception was the direct cause of the following exception:\n\n', 'Traceback (most recent call last):\n', '  File "/home/sosna/inzz/tempp/quad_cross/quad_learn_2.py", line 426, in learn\n    visualize.draw_net(config, winner, view=False, filename=os.path.join(\n', '  File "/home/sosna/inzz/tempp/quad_cross/visualize.py", line 182, in draw_net\n    dot.render(filename, view=view)\n', '  File "/home/sosna/.local/lib/python3.12/site-packages/graphviz/_tools.py", line 171, in wrapper\n    return func(*args, **kwargs)\n           ^^^^^^^^^^^^^^^^^^^^^\n', '  File "/home/sosna/.local/lib/python3.12/site-packages/graphviz/rendering.py", line 122, in render\n    rendered = self._render(*args, **kwargs)\n               ^^^^^^^^^^^^^^^^^^^^^^^^^^^^^\n', '  File "/home/sosna/.local/lib/python3.12/site-packages/graphviz/_tools.py", line 171, in wrapper\n    return func(*args, **kwargs)\n           ^^^^^^^^^^^^^^^^^^^^^\n', '  File "/home/sosna/.local/lib/python3.12/site-packages/graphviz/backend/rendering.py", line 326, in render\n    execute.run_check(cmd,\n', '  File "/home/sosna/.local/lib/python3.12/site-packages/graphviz/backend/execute.py", line 81, in run_check\n    raise ExecutableNotFound(cmd) from e\n', "graphviz.backend.execute.ExecutableNotFound: failed to execute PosixPath('dot'), make sure the Graphviz executables are on your systems' PATH\n"]

failed to execute PosixPath('dot'), make sure the Graphviz executables are on your systems' PATH
['Traceback (most recent call last):\n', '  File "/home/sosna/.local/lib/python3.12/site-packages/graphviz/backend/execute.py", line 78, in run_check\n    proc = subprocess.run(cmd, **kwargs)\n           ^^^^^^^^^^^^^^^^^^^^^^^^^^^^^\n', '  File "/usr/lib/python3.12/subprocess.py", line 548, in run\n    with Popen(*popenargs, **kwargs) as process:\n         ^^^^^^^^^^^^^^^^^^^^^^^^^^^\n', '  File "/usr/lib/python3.12/subprocess.py", line 1026, in __init__\n    self._execute_child(args, executable, preexec_fn, close_fds,\n', '  File "/usr/lib/python3.12/subprocess.py", line 1955, in _execute_child\n    raise child_exception_type(errno_num, err_msg, err_filename)\n', "FileNotFoundError: [Errno 2] No such file or directory: PosixPath('dot')\n", '\nThe above exception was the direct cause of the following exception:\n\n', 'Traceback (most recent call last):\n', '  File "/home/sosna/inzz/tempp/quad_cross/quad_learn_2.py", line 426, in learn\n    visualize.draw_net(config, winner, view=False, filename=os.path.join(\n', '  File "/home/sosna/inzz/tempp/quad_cross/visualize.py", line 182, in draw_net\n    dot.render(filename, view=view)\n', '  File "/home/sosna/.local/lib/python3.12/site-packages/graphviz/_tools.py", line 171, in wrapper\n    return func(*args, **kwargs)\n           ^^^^^^^^^^^^^^^^^^^^^\n', '  File "/home/sosna/.local/lib/python3.12/site-packages/graphviz/rendering.py", line 122, in render\n    rendered = self._render(*args, **kwargs)\n               ^^^^^^^^^^^^^^^^^^^^^^^^^^^^^\n', '  File "/home/sosna/.local/lib/python3.12/site-packages/graphviz/_tools.py", line 171, in wrapper\n    return func(*args, **kwargs)\n           ^^^^^^^^^^^^^^^^^^^^^\n', '  File "/home/sosna/.local/lib/python3.12/site-packages/graphviz/backend/rendering.py", line 326, in render\n    execute.run_check(cmd,\n', '  File "/home/sosna/.local/lib/python3.12/site-packages/graphviz/backend/execute.py", line 81, in run_check\n    raise ExecutableNotFound(cmd) from e\n', "graphviz.backend.execute.ExecutableNotFound: failed to execute PosixPath('dot'), make sure the Graphviz executables are on your systems' PATH\n"]

failed to execute PosixPath('dot'), make sure the Graphviz executables are on your systems' PATH
['Traceback (most recent call last):\n', '  File "/home/sosna/.local/lib/python3.12/site-packages/graphviz/backend/execute.py", line 78, in run_check\n    proc = subprocess.run(cmd, **kwargs)\n           ^^^^^^^^^^^^^^^^^^^^^^^^^^^^^\n', '  File "/usr/lib/python3.12/subprocess.py", line 548, in run\n    with Popen(*popenargs, **kwargs) as process:\n         ^^^^^^^^^^^^^^^^^^^^^^^^^^^\n', '  File "/usr/lib/python3.12/subprocess.py", line 1026, in __init__\n    self._execute_child(args, executable, preexec_fn, close_fds,\n', '  File "/usr/lib/python3.12/subprocess.py", line 1955, in _execute_child\n    raise child_exception_type(errno_num, err_msg, err_filename)\n', "FileNotFoundError: [Errno 2] No such file or directory: PosixPath('dot')\n", '\nThe above exception was the direct cause of the following exception:\n\n', 'Traceback (most recent call last):\n', '  File "/home/sosna/inzz/tempp/quad_cross/quad_learn_2.py", line 426, in learn\n    visualize.draw_net(config, winner, view=False, filename=os.path.join(\n', '  File "/home/sosna/inzz/tempp/quad_cross/visualize.py", line 182, in draw_net\n    dot.render(filename, view=view)\n', '  File "/home/sosna/.local/lib/python3.12/site-packages/graphviz/_tools.py", line 171, in wrapper\n    return func(*args, **kwargs)\n           ^^^^^^^^^^^^^^^^^^^^^\n', '  File "/home/sosna/.local/lib/python3.12/site-packages/graphviz/rendering.py", line 122, in render\n    rendered = self._render(*args, **kwargs)\n               ^^^^^^^^^^^^^^^^^^^^^^^^^^^^^\n', '  File "/home/sosna/.local/lib/python3.12/site-packages/graphviz/_tools.py", line 171, in wrapper\n    return func(*args, **kwargs)\n           ^^^^^^^^^^^^^^^^^^^^^\n', '  File "/home/sosna/.local/lib/python3.12/site-packages/graphviz/backend/rendering.py", line 326, in render\n    execute.run_check(cmd,\n', '  File "/home/sosna/.local/lib/python3.12/site-packages/graphviz/backend/execute.py", line 81, in run_check\n    raise ExecutableNotFound(cmd) from e\n', "graphviz.backend.execute.ExecutableNotFound: failed to execute PosixPath('dot'), make sure the Graphviz executables are on your systems' PATH\n"]

failed to execute PosixPath('dot'), make sure the Graphviz executables are on your systems' PATH
['Traceback (most recent call last):\n', '  File "/home/sosna/.local/lib/python3.12/site-packages/graphviz/backend/execute.py", line 78, in run_check\n    proc = subprocess.run(cmd, **kwargs)\n           ^^^^^^^^^^^^^^^^^^^^^^^^^^^^^\n', '  File "/usr/lib/python3.12/subprocess.py", line 548, in run\n    with Popen(*popenargs, **kwargs) as process:\n         ^^^^^^^^^^^^^^^^^^^^^^^^^^^\n', '  File "/usr/lib/python3.12/subprocess.py", line 1026, in __init__\n    self._execute_child(args, executable, preexec_fn, close_fds,\n', '  File "/usr/lib/python3.12/subprocess.py", line 1955, in _execute_child\n    raise child_exception_type(errno_num, err_msg, err_filename)\n', "FileNotFoundError: [Errno 2] No such file or directory: PosixPath('dot')\n", '\nThe above exception was the direct cause of the following exception:\n\n', 'Traceback (most recent call last):\n', '  File "/home/sosna/inzz/tempp/quad_cross/quad_learn_2.py", line 426, in learn\n    visualize.draw_net(config, winner, view=False, filename=os.path.join(\n', '  File "/home/sosna/inzz/tempp/quad_cross/visualize.py", line 182, in draw_net\n    dot.render(filename, view=view)\n', '  File "/home/sosna/.local/lib/python3.12/site-packages/graphviz/_tools.py", line 171, in wrapper\n    return func(*args, **kwargs)\n           ^^^^^^^^^^^^^^^^^^^^^\n', '  File "/home/sosna/.local/lib/python3.12/site-packages/graphviz/rendering.py", line 122, in render\n    rendered = self._render(*args, **kwargs)\n               ^^^^^^^^^^^^^^^^^^^^^^^^^^^^^\n', '  File "/home/sosna/.local/lib/python3.12/site-packages/graphviz/_tools.py", line 171, in wrapper\n    return func(*args, **kwargs)\n           ^^^^^^^^^^^^^^^^^^^^^\n', '  File "/home/sosna/.local/lib/python3.12/site-packages/graphviz/backend/rendering.py", line 326, in render\n    execute.run_check(cmd,\n', '  File "/home/sosna/.local/lib/python3.12/site-packages/graphviz/backend/execute.py", line 81, in run_check\n    raise ExecutableNotFound(cmd) from e\n', "graphviz.backend.execute.ExecutableNotFound: failed to execute PosixPath('dot'), make sure the Graphviz executables are on your systems' PATH\n"]

failed to execute PosixPath('dot'), make sure the Graphviz executables are on your systems' PATH
['Traceback (most recent call last):\n', '  File "/home/sosna/.local/lib/python3.12/site-packages/graphviz/backend/execute.py", line 78, in run_check\n    proc = subprocess.run(cmd, **kwargs)\n           ^^^^^^^^^^^^^^^^^^^^^^^^^^^^^\n', '  File "/usr/lib/python3.12/subprocess.py", line 548, in run\n    with Popen(*popenargs, **kwargs) as process:\n         ^^^^^^^^^^^^^^^^^^^^^^^^^^^\n', '  File "/usr/lib/python3.12/subprocess.py", line 1026, in __init__\n    self._execute_child(args, executable, preexec_fn, close_fds,\n', '  File "/usr/lib/python3.12/subprocess.py", line 1955, in _execute_child\n    raise child_exception_type(errno_num, err_msg, err_filename)\n', "FileNotFoundError: [Errno 2] No such file or directory: PosixPath('dot')\n", '\nThe above exception was the direct cause of the following exception:\n\n', 'Traceback (most recent call last):\n', '  File "/home/sosna/inzz/tempp/quad_cross/quad_learn_2.py", line 426, in learn\n    visualize.draw_net(config, winner, view=False, filename=os.path.join(\n', '  File "/home/sosna/inzz/tempp/quad_cross/visualize.py", line 182, in draw_net\n    dot.render(filename, view=view)\n', '  File "/home/sosna/.local/lib/python3.12/site-packages/graphviz/_tools.py", line 171, in wrapper\n    return func(*args, **kwargs)\n           ^^^^^^^^^^^^^^^^^^^^^\n', '  File "/home/sosna/.local/lib/python3.12/site-packages/graphviz/rendering.py", line 122, in render\n    rendered = self._render(*args, **kwargs)\n               ^^^^^^^^^^^^^^^^^^^^^^^^^^^^^\n', '  File "/home/sosna/.local/lib/python3.12/site-packages/graphviz/_tools.py", line 171, in wrapper\n    return func(*args, **kwargs)\n           ^^^^^^^^^^^^^^^^^^^^^\n', '  File "/home/sosna/.local/lib/python3.12/site-packages/graphviz/backend/rendering.py", line 326, in render\n    execute.run_check(cmd,\n', '  File "/home/sosna/.local/lib/python3.12/site-packages/graphviz/backend/execute.py", line 81, in run_check\n    raise ExecutableNotFound(cmd) from e\n', "graphviz.backend.execute.ExecutableNotFound: failed to execute PosixPath('dot'), make sure the Graphviz executables are on your systems' PATH\n"]

failed to execute PosixPath('dot'), make sure the Graphviz executables are on your systems' PATH
['Traceback (most recent call last):\n', '  File "/home/sosna/.local/lib/python3.12/site-packages/graphviz/backend/execute.py", line 78, in run_check\n    proc = subprocess.run(cmd, **kwargs)\n           ^^^^^^^^^^^^^^^^^^^^^^^^^^^^^\n', '  File "/usr/lib/python3.12/subprocess.py", line 548, in run\n    with Popen(*popenargs, **kwargs) as process:\n         ^^^^^^^^^^^^^^^^^^^^^^^^^^^\n', '  File "/usr/lib/python3.12/subprocess.py", line 1026, in __init__\n    self._execute_child(args, executable, preexec_fn, close_fds,\n', '  File "/usr/lib/python3.12/subprocess.py", line 1955, in _execute_child\n    raise child_exception_type(errno_num, err_msg, err_filename)\n', "FileNotFoundError: [Errno 2] No such file or directory: PosixPath('dot')\n", '\nThe above exception was the direct cause of the following exception:\n\n', 'Traceback (most recent call last):\n', '  File "/home/sosna/inzz/tempp/quad_cross/quad_learn_2.py", line 426, in learn\n    visualize.draw_net(config, winner, view=False, filename=os.path.join(\n', '  File "/home/sosna/inzz/tempp/quad_cross/visualize.py", line 182, in draw_net\n    dot.render(filename, view=view)\n', '  File "/home/sosna/.local/lib/python3.12/site-packages/graphviz/_tools.py", line 171, in wrapper\n    return func(*args, **kwargs)\n           ^^^^^^^^^^^^^^^^^^^^^\n', '  File "/home/sosna/.local/lib/python3.12/site-packages/graphviz/rendering.py", line 122, in render\n    rendered = self._render(*args, **kwargs)\n               ^^^^^^^^^^^^^^^^^^^^^^^^^^^^^\n', '  File "/home/sosna/.local/lib/python3.12/site-packages/graphviz/_tools.py", line 171, in wrapper\n    return func(*args, **kwargs)\n           ^^^^^^^^^^^^^^^^^^^^^\n', '  File "/home/sosna/.local/lib/python3.12/site-packages/graphviz/backend/rendering.py", line 326, in render\n    execute.run_check(cmd,\n', '  File "/home/sosna/.local/lib/python3.12/site-packages/graphviz/backend/execute.py", line 81, in run_check\n    raise ExecutableNotFound(cmd) from e\n', "graphviz.backend.execute.ExecutableNotFound: failed to execute PosixPath('dot'), make sure the Graphviz executables are on your systems' PATH\n"]

failed to execute PosixPath('dot'), make sure the Graphviz executables are on your systems' PATH
['Traceback (most recent call last):\n', '  File "/home/sosna/.local/lib/python3.12/site-packages/graphviz/backend/execute.py", line 78, in run_check\n    proc = subprocess.run(cmd, **kwargs)\n           ^^^^^^^^^^^^^^^^^^^^^^^^^^^^^\n', '  File "/usr/lib/python3.12/subprocess.py", line 548, in run\n    with Popen(*popenargs, **kwargs) as process:\n         ^^^^^^^^^^^^^^^^^^^^^^^^^^^\n', '  File "/usr/lib/python3.12/subprocess.py", line 1026, in __init__\n    self._execute_child(args, executable, preexec_fn, close_fds,\n', '  File "/usr/lib/python3.12/subprocess.py", line 1955, in _execute_child\n    raise child_exception_type(errno_num, err_msg, err_filename)\n', "FileNotFoundError: [Errno 2] No such file or directory: PosixPath('dot')\n", '\nThe above exception was the direct cause of the following exception:\n\n', 'Traceback (most recent call last):\n', '  File "/home/sosna/inzz/tempp/quad_cross/quad_learn_2.py", line 426, in learn\n    visualize.draw_net(config, winner, view=False, filename=os.path.join(\n', '  File "/home/sosna/inzz/tempp/quad_cross/visualize.py", line 182, in draw_net\n    dot.render(filename, view=view)\n', '  File "/home/sosna/.local/lib/python3.12/site-packages/graphviz/_tools.py", line 171, in wrapper\n    return func(*args, **kwargs)\n           ^^^^^^^^^^^^^^^^^^^^^\n', '  File "/home/sosna/.local/lib/python3.12/site-packages/graphviz/rendering.py", line 122, in render\n    rendered = self._render(*args, **kwargs)\n               ^^^^^^^^^^^^^^^^^^^^^^^^^^^^^\n', '  File "/home/sosna/.local/lib/python3.12/site-packages/graphviz/_tools.py", line 171, in wrapper\n    return func(*args, **kwargs)\n           ^^^^^^^^^^^^^^^^^^^^^\n', '  File "/home/sosna/.local/lib/python3.12/site-packages/graphviz/backend/rendering.py", line 326, in render\n    execute.run_check(cmd,\n', '  File "/home/sosna/.local/lib/python3.12/site-packages/graphviz/backend/execute.py", line 81, in run_check\n    raise ExecutableNotFound(cmd) from e\n', "graphviz.backend.execute.ExecutableNotFound: failed to execute PosixPath('dot'), make sure the Graphviz executables are on your systems' PATH\n"]

failed to execute PosixPath('dot'), make sure the Graphviz executables are on your systems' PATH
['Traceback (most recent call last):\n', '  File "/home/sosna/.local/lib/python3.12/site-packages/graphviz/backend/execute.py", line 78, in run_check\n    proc = subprocess.run(cmd, **kwargs)\n           ^^^^^^^^^^^^^^^^^^^^^^^^^^^^^\n', '  File "/usr/lib/python3.12/subprocess.py", line 548, in run\n    with Popen(*popenargs, **kwargs) as process:\n         ^^^^^^^^^^^^^^^^^^^^^^^^^^^\n', '  File "/usr/lib/python3.12/subprocess.py", line 1026, in __init__\n    self._execute_child(args, executable, preexec_fn, close_fds,\n', '  File "/usr/lib/python3.12/subprocess.py", line 1955, in _execute_child\n    raise child_exception_type(errno_num, err_msg, err_filename)\n', "FileNotFoundError: [Errno 2] No such file or directory: PosixPath('dot')\n", '\nThe above exception was the direct cause of the following exception:\n\n', 'Traceback (most recent call last):\n', '  File "/home/sosna/inzz/tempp/quad_cross/quad_learn_2.py", line 426, in learn\n    visualize.draw_net(config, winner, view=False, filename=os.path.join(\n', '  File "/home/sosna/inzz/tempp/quad_cross/visualize.py", line 182, in draw_net\n    dot.render(filename, view=view)\n', '  File "/home/sosna/.local/lib/python3.12/site-packages/graphviz/_tools.py", line 171, in wrapper\n    return func(*args, **kwargs)\n           ^^^^^^^^^^^^^^^^^^^^^\n', '  File "/home/sosna/.local/lib/python3.12/site-packages/graphviz/rendering.py", line 122, in render\n    rendered = self._render(*args, **kwargs)\n               ^^^^^^^^^^^^^^^^^^^^^^^^^^^^^\n', '  File "/home/sosna/.local/lib/python3.12/site-packages/graphviz/_tools.py", line 171, in wrapper\n    return func(*args, **kwargs)\n           ^^^^^^^^^^^^^^^^^^^^^\n', '  File "/home/sosna/.local/lib/python3.12/site-packages/graphviz/backend/rendering.py", line 326, in render\n    execute.run_check(cmd,\n', '  File "/home/sosna/.local/lib/python3.12/site-packages/graphviz/backend/execute.py", line 81, in run_check\n    raise ExecutableNotFound(cmd) from e\n', "graphviz.backend.execute.ExecutableNotFound: failed to execute PosixPath('dot'), make sure the Graphviz executables are on your systems' PATH\n"]

failed to execute PosixPath('dot'), make sure the Graphviz executables are on your systems' PATH
['Traceback (most recent call last):\n', '  File "/home/sosna/.local/lib/python3.12/site-packages/graphviz/backend/execute.py", line 78, in run_check\n    proc = subprocess.run(cmd, **kwargs)\n           ^^^^^^^^^^^^^^^^^^^^^^^^^^^^^\n', '  File "/usr/lib/python3.12/subprocess.py", line 548, in run\n    with Popen(*popenargs, **kwargs) as process:\n         ^^^^^^^^^^^^^^^^^^^^^^^^^^^\n', '  File "/usr/lib/python3.12/subprocess.py", line 1026, in __init__\n    self._execute_child(args, executable, preexec_fn, close_fds,\n', '  File "/usr/lib/python3.12/subprocess.py", line 1955, in _execute_child\n    raise child_exception_type(errno_num, err_msg, err_filename)\n', "FileNotFoundError: [Errno 2] No such file or directory: PosixPath('dot')\n", '\nThe above exception was the direct cause of the following exception:\n\n', 'Traceback (most recent call last):\n', '  File "/home/sosna/inzz/tempp/quad_cross/quad_learn_2.py", line 426, in learn\n    visualize.draw_net(config, winner, view=False, filename=os.path.join(\n', '  File "/home/sosna/inzz/tempp/quad_cross/visualize.py", line 182, in draw_net\n    dot.render(filename, view=view)\n', '  File "/home/sosna/.local/lib/python3.12/site-packages/graphviz/_tools.py", line 171, in wrapper\n    return func(*args, **kwargs)\n           ^^^^^^^^^^^^^^^^^^^^^\n', '  File "/home/sosna/.local/lib/python3.12/site-packages/graphviz/rendering.py", line 122, in render\n    rendered = self._render(*args, **kwargs)\n               ^^^^^^^^^^^^^^^^^^^^^^^^^^^^^\n', '  File "/home/sosna/.local/lib/python3.12/site-packages/graphviz/_tools.py", line 171, in wrapper\n    return func(*args, **kwargs)\n           ^^^^^^^^^^^^^^^^^^^^^\n', '  File "/home/sosna/.local/lib/python3.12/site-packages/graphviz/backend/rendering.py", line 326, in render\n    execute.run_check(cmd,\n', '  File "/home/sosna/.local/lib/python3.12/site-packages/graphviz/backend/execute.py", line 81, in run_check\n    raise ExecutableNotFound(cmd) from e\n', "graphviz.backend.execute.ExecutableNotFound: failed to execute PosixPath('dot'), make sure the Graphviz executables are on your systems' PATH\n"]

failed to execute PosixPath('dot'), make sure the Graphviz executables are on your systems' PATH
['Traceback (most recent call last):\n', '  File "/home/sosna/.local/lib/python3.12/site-packages/graphviz/backend/execute.py", line 78, in run_check\n    proc = subprocess.run(cmd, **kwargs)\n           ^^^^^^^^^^^^^^^^^^^^^^^^^^^^^\n', '  File "/usr/lib/python3.12/subprocess.py", line 548, in run\n    with Popen(*popenargs, **kwargs) as process:\n         ^^^^^^^^^^^^^^^^^^^^^^^^^^^\n', '  File "/usr/lib/python3.12/subprocess.py", line 1026, in __init__\n    self._execute_child(args, executable, preexec_fn, close_fds,\n', '  File "/usr/lib/python3.12/subprocess.py", line 1955, in _execute_child\n    raise child_exception_type(errno_num, err_msg, err_filename)\n', "FileNotFoundError: [Errno 2] No such file or directory: PosixPath('dot')\n", '\nThe above exception was the direct cause of the following exception:\n\n', 'Traceback (most recent call last):\n', '  File "/home/sosna/inzz/tempp/quad_cross/quad_learn_2.py", line 426, in learn\n    visualize.draw_net(config, winner, view=False, filename=os.path.join(\n', '  File "/home/sosna/inzz/tempp/quad_cross/visualize.py", line 182, in draw_net\n    dot.render(filename, view=view)\n', '  File "/home/sosna/.local/lib/python3.12/site-packages/graphviz/_tools.py", line 171, in wrapper\n    return func(*args, **kwargs)\n           ^^^^^^^^^^^^^^^^^^^^^\n', '  File "/home/sosna/.local/lib/python3.12/site-packages/graphviz/rendering.py", line 122, in render\n    rendered = self._render(*args, **kwargs)\n               ^^^^^^^^^^^^^^^^^^^^^^^^^^^^^\n', '  File "/home/sosna/.local/lib/python3.12/site-packages/graphviz/_tools.py", line 171, in wrapper\n    return func(*args, **kwargs)\n           ^^^^^^^^^^^^^^^^^^^^^\n', '  File "/home/sosna/.local/lib/python3.12/site-packages/graphviz/backend/rendering.py", line 326, in render\n    execute.run_check(cmd,\n', '  File "/home/sosna/.local/lib/python3.12/site-packages/graphviz/backend/execute.py", line 81, in run_check\n    raise ExecutableNotFound(cmd) from e\n', "graphviz.backend.execute.ExecutableNotFound: failed to execute PosixPath('dot'), make sure the Graphviz executables are on your systems' PATH\n"]

failed to execute PosixPath('dot'), make sure the Graphviz executables are on your systems' PATH
['Traceback (most recent call last):\n', '  File "/home/sosna/.local/lib/python3.12/site-packages/graphviz/backend/execute.py", line 78, in run_check\n    proc = subprocess.run(cmd, **kwargs)\n           ^^^^^^^^^^^^^^^^^^^^^^^^^^^^^\n', '  File "/usr/lib/python3.12/subprocess.py", line 548, in run\n    with Popen(*popenargs, **kwargs) as process:\n         ^^^^^^^^^^^^^^^^^^^^^^^^^^^\n', '  File "/usr/lib/python3.12/subprocess.py", line 1026, in __init__\n    self._execute_child(args, executable, preexec_fn, close_fds,\n', '  File "/usr/lib/python3.12/subprocess.py", line 1955, in _execute_child\n    raise child_exception_type(errno_num, err_msg, err_filename)\n', "FileNotFoundError: [Errno 2] No such file or directory: PosixPath('dot')\n", '\nThe above exception was the direct cause of the following exception:\n\n', 'Traceback (most recent call last):\n', '  File "/home/sosna/inzz/tempp/quad_cross/quad_learn_2.py", line 426, in learn\n    visualize.draw_net(config, winner, view=False, filename=os.path.join(\n', '  File "/home/sosna/inzz/tempp/quad_cross/visualize.py", line 182, in draw_net\n    dot.render(filename, view=view)\n', '  File "/home/sosna/.local/lib/python3.12/site-packages/graphviz/_tools.py", line 171, in wrapper\n    return func(*args, **kwargs)\n           ^^^^^^^^^^^^^^^^^^^^^\n', '  File "/home/sosna/.local/lib/python3.12/site-packages/graphviz/rendering.py", line 122, in render\n    rendered = self._render(*args, **kwargs)\n               ^^^^^^^^^^^^^^^^^^^^^^^^^^^^^\n', '  File "/home/sosna/.local/lib/python3.12/site-packages/graphviz/_tools.py", line 171, in wrapper\n    return func(*args, **kwargs)\n           ^^^^^^^^^^^^^^^^^^^^^\n', '  File "/home/sosna/.local/lib/python3.12/site-packages/graphviz/backend/rendering.py", line 326, in render\n    execute.run_check(cmd,\n', '  File "/home/sosna/.local/lib/python3.12/site-packages/graphviz/backend/execute.py", line 81, in run_check\n    raise ExecutableNotFound(cmd) from e\n', "graphviz.backend.execute.ExecutableNotFound: failed to execute PosixPath('dot'), make sure the Graphviz executables are on your systems' PATH\n"]

failed to execute PosixPath('dot'), make sure the Graphviz executables are on your systems' PATH
['Traceback (most recent call last):\n', '  File "/home/sosna/.local/lib/python3.12/site-packages/graphviz/backend/execute.py", line 78, in run_check\n    proc = subprocess.run(cmd, **kwargs)\n           ^^^^^^^^^^^^^^^^^^^^^^^^^^^^^\n', '  File "/usr/lib/python3.12/subprocess.py", line 548, in run\n    with Popen(*popenargs, **kwargs) as process:\n         ^^^^^^^^^^^^^^^^^^^^^^^^^^^\n', '  File "/usr/lib/python3.12/subprocess.py", line 1026, in __init__\n    self._execute_child(args, executable, preexec_fn, close_fds,\n', '  File "/usr/lib/python3.12/subprocess.py", line 1955, in _execute_child\n    raise child_exception_type(errno_num, err_msg, err_filename)\n', "FileNotFoundError: [Errno 2] No such file or directory: PosixPath('dot')\n", '\nThe above exception was the direct cause of the following exception:\n\n', 'Traceback (most recent call last):\n', '  File "/home/sosna/inzz/tempp/quad_cross/quad_learn_2.py", line 426, in learn\n    visualize.draw_net(config, winner, view=False, filename=os.path.join(\n', '  File "/home/sosna/inzz/tempp/quad_cross/visualize.py", line 182, in draw_net\n    dot.render(filename, view=view)\n', '  File "/home/sosna/.local/lib/python3.12/site-packages/graphviz/_tools.py", line 171, in wrapper\n    return func(*args, **kwargs)\n           ^^^^^^^^^^^^^^^^^^^^^\n', '  File "/home/sosna/.local/lib/python3.12/site-packages/graphviz/rendering.py", line 122, in render\n    rendered = self._render(*args, **kwargs)\n               ^^^^^^^^^^^^^^^^^^^^^^^^^^^^^\n', '  File "/home/sosna/.local/lib/python3.12/site-packages/graphviz/_tools.py", line 171, in wrapper\n    return func(*args, **kwargs)\n           ^^^^^^^^^^^^^^^^^^^^^\n', '  File "/home/sosna/.local/lib/python3.12/site-packages/graphviz/backend/rendering.py", line 326, in render\n    execute.run_check(cmd,\n', '  File "/home/sosna/.local/lib/python3.12/site-packages/graphviz/backend/execute.py", line 81, in run_check\n    raise ExecutableNotFound(cmd) from e\n', "graphviz.backend.execute.ExecutableNotFound: failed to execute PosixPath('dot'), make sure the Graphviz executables are on your systems' PATH\n"]

failed to execute PosixPath('dot'), make sure the Graphviz executables are on your systems' PATH
['Traceback (most recent call last):\n', '  File "/home/sosna/.local/lib/python3.12/site-packages/graphviz/backend/execute.py", line 78, in run_check\n    proc = subprocess.run(cmd, **kwargs)\n           ^^^^^^^^^^^^^^^^^^^^^^^^^^^^^\n', '  File "/usr/lib/python3.12/subprocess.py", line 548, in run\n    with Popen(*popenargs, **kwargs) as process:\n         ^^^^^^^^^^^^^^^^^^^^^^^^^^^\n', '  File "/usr/lib/python3.12/subprocess.py", line 1026, in __init__\n    self._execute_child(args, executable, preexec_fn, close_fds,\n', '  File "/usr/lib/python3.12/subprocess.py", line 1955, in _execute_child\n    raise child_exception_type(errno_num, err_msg, err_filename)\n', "FileNotFoundError: [Errno 2] No such file or directory: PosixPath('dot')\n", '\nThe above exception was the direct cause of the following exception:\n\n', 'Traceback (most recent call last):\n', '  File "/home/sosna/inzz/tempp/quad_cross/quad_learn_2.py", line 426, in learn\n    visualize.draw_net(config, winner, view=False, filename=os.path.join(\n', '  File "/home/sosna/inzz/tempp/quad_cross/visualize.py", line 182, in draw_net\n    dot.render(filename, view=view)\n', '  File "/home/sosna/.local/lib/python3.12/site-packages/graphviz/_tools.py", line 171, in wrapper\n    return func(*args, **kwargs)\n           ^^^^^^^^^^^^^^^^^^^^^\n', '  File "/home/sosna/.local/lib/python3.12/site-packages/graphviz/rendering.py", line 122, in render\n    rendered = self._render(*args, **kwargs)\n               ^^^^^^^^^^^^^^^^^^^^^^^^^^^^^\n', '  File "/home/sosna/.local/lib/python3.12/site-packages/graphviz/_tools.py", line 171, in wrapper\n    return func(*args, **kwargs)\n           ^^^^^^^^^^^^^^^^^^^^^\n', '  File "/home/sosna/.local/lib/python3.12/site-packages/graphviz/backend/rendering.py", line 326, in render\n    execute.run_check(cmd,\n', '  File "/home/sosna/.local/lib/python3.12/site-packages/graphviz/backend/execute.py", line 81, in run_check\n    raise ExecutableNotFound(cmd) from e\n', "graphviz.backend.execute.ExecutableNotFound: failed to execute PosixPath('dot'), make sure the Graphviz executables are on your systems' PATH\n"]

failed to execute PosixPath('dot'), make sure the Graphviz executables are on your systems' PATH
['Traceback (most recent call last):\n', '  File "/home/sosna/.local/lib/python3.12/site-packages/graphviz/backend/execute.py", line 78, in run_check\n    proc = subprocess.run(cmd, **kwargs)\n           ^^^^^^^^^^^^^^^^^^^^^^^^^^^^^\n', '  File "/usr/lib/python3.12/subprocess.py", line 548, in run\n    with Popen(*popenargs, **kwargs) as process:\n         ^^^^^^^^^^^^^^^^^^^^^^^^^^^\n', '  File "/usr/lib/python3.12/subprocess.py", line 1026, in __init__\n    self._execute_child(args, executable, preexec_fn, close_fds,\n', '  File "/usr/lib/python3.12/subprocess.py", line 1955, in _execute_child\n    raise child_exception_type(errno_num, err_msg, err_filename)\n', "FileNotFoundError: [Errno 2] No such file or directory: PosixPath('dot')\n", '\nThe above exception was the direct cause of the following exception:\n\n', 'Traceback (most recent call last):\n', '  File "/home/sosna/inzz/tempp/quad_cross/quad_learn_2.py", line 426, in learn\n    visualize.draw_net(config, winner, view=False, filename=os.path.join(\n', '  File "/home/sosna/inzz/tempp/quad_cross/visualize.py", line 182, in draw_net\n    dot.render(filename, view=view)\n', '  File "/home/sosna/.local/lib/python3.12/site-packages/graphviz/_tools.py", line 171, in wrapper\n    return func(*args, **kwargs)\n           ^^^^^^^^^^^^^^^^^^^^^\n', '  File "/home/sosna/.local/lib/python3.12/site-packages/graphviz/rendering.py", line 122, in render\n    rendered = self._render(*args, **kwargs)\n               ^^^^^^^^^^^^^^^^^^^^^^^^^^^^^\n', '  File "/home/sosna/.local/lib/python3.12/site-packages/graphviz/_tools.py", line 171, in wrapper\n    return func(*args, **kwargs)\n           ^^^^^^^^^^^^^^^^^^^^^\n', '  File "/home/sosna/.local/lib/python3.12/site-packages/graphviz/backend/rendering.py", line 326, in render\n    execute.run_check(cmd,\n', '  File "/home/sosna/.local/lib/python3.12/site-packages/graphviz/backend/execute.py", line 81, in run_check\n    raise ExecutableNotFound(cmd) from e\n', "graphviz.backend.execute.ExecutableNotFound: failed to execute PosixPath('dot'), make sure the Graphviz executables are on your systems' PATH\n"]

failed to execute PosixPath('dot'), make sure the Graphviz executables are on your systems' PATH
['Traceback (most recent call last):\n', '  File "/home/sosna/.local/lib/python3.12/site-packages/graphviz/backend/execute.py", line 78, in run_check\n    proc = subprocess.run(cmd, **kwargs)\n           ^^^^^^^^^^^^^^^^^^^^^^^^^^^^^\n', '  File "/usr/lib/python3.12/subprocess.py", line 548, in run\n    with Popen(*popenargs, **kwargs) as process:\n         ^^^^^^^^^^^^^^^^^^^^^^^^^^^\n', '  File "/usr/lib/python3.12/subprocess.py", line 1026, in __init__\n    self._execute_child(args, executable, preexec_fn, close_fds,\n', '  File "/usr/lib/python3.12/subprocess.py", line 1955, in _execute_child\n    raise child_exception_type(errno_num, err_msg, err_filename)\n', "FileNotFoundError: [Errno 2] No such file or directory: PosixPath('dot')\n", '\nThe above exception was the direct cause of the following exception:\n\n', 'Traceback (most recent call last):\n', '  File "/home/sosna/inzz/tempp/quad_cross/quad_learn_2.py", line 426, in learn\n    visualize.draw_net(config, winner, view=False, filename=os.path.join(\n', '  File "/home/sosna/inzz/tempp/quad_cross/visualize.py", line 182, in draw_net\n    dot.render(filename, view=view)\n', '  File "/home/sosna/.local/lib/python3.12/site-packages/graphviz/_tools.py", line 171, in wrapper\n    return func(*args, **kwargs)\n           ^^^^^^^^^^^^^^^^^^^^^\n', '  File "/home/sosna/.local/lib/python3.12/site-packages/graphviz/rendering.py", line 122, in render\n    rendered = self._render(*args, **kwargs)\n               ^^^^^^^^^^^^^^^^^^^^^^^^^^^^^\n', '  File "/home/sosna/.local/lib/python3.12/site-packages/graphviz/_tools.py", line 171, in wrapper\n    return func(*args, **kwargs)\n           ^^^^^^^^^^^^^^^^^^^^^\n', '  File "/home/sosna/.local/lib/python3.12/site-packages/graphviz/backend/rendering.py", line 326, in render\n    execute.run_check(cmd,\n', '  File "/home/sosna/.local/lib/python3.12/site-packages/graphviz/backend/execute.py", line 81, in run_check\n    raise ExecutableNotFound(cmd) from e\n', "graphviz.backend.execute.ExecutableNotFound: failed to execute PosixPath('dot'), make sure the Graphviz executables are on your systems' PATH\n"]

failed to execute PosixPath('dot'), make sure the Graphviz executables are on your systems' PATH
['Traceback (most recent call last):\n', '  File "/home/sosna/.local/lib/python3.12/site-packages/graphviz/backend/execute.py", line 78, in run_check\n    proc = subprocess.run(cmd, **kwargs)\n           ^^^^^^^^^^^^^^^^^^^^^^^^^^^^^\n', '  File "/usr/lib/python3.12/subprocess.py", line 548, in run\n    with Popen(*popenargs, **kwargs) as process:\n         ^^^^^^^^^^^^^^^^^^^^^^^^^^^\n', '  File "/usr/lib/python3.12/subprocess.py", line 1026, in __init__\n    self._execute_child(args, executable, preexec_fn, close_fds,\n', '  File "/usr/lib/python3.12/subprocess.py", line 1955, in _execute_child\n    raise child_exception_type(errno_num, err_msg, err_filename)\n', "FileNotFoundError: [Errno 2] No such file or directory: PosixPath('dot')\n", '\nThe above exception was the direct cause of the following exception:\n\n', 'Traceback (most recent call last):\n', '  File "/home/sosna/inzz/tempp/quad_cross/quad_learn_2.py", line 426, in learn\n    visualize.draw_net(config, winner, view=False, filename=os.path.join(\n', '  File "/home/sosna/inzz/tempp/quad_cross/visualize.py", line 182, in draw_net\n    dot.render(filename, view=view)\n', '  File "/home/sosna/.local/lib/python3.12/site-packages/graphviz/_tools.py", line 171, in wrapper\n    return func(*args, **kwargs)\n           ^^^^^^^^^^^^^^^^^^^^^\n', '  File "/home/sosna/.local/lib/python3.12/site-packages/graphviz/rendering.py", line 122, in render\n    rendered = self._render(*args, **kwargs)\n               ^^^^^^^^^^^^^^^^^^^^^^^^^^^^^\n', '  File "/home/sosna/.local/lib/python3.12/site-packages/graphviz/_tools.py", line 171, in wrapper\n    return func(*args, **kwargs)\n           ^^^^^^^^^^^^^^^^^^^^^\n', '  File "/home/sosna/.local/lib/python3.12/site-packages/graphviz/backend/rendering.py", line 326, in render\n    execute.run_check(cmd,\n', '  File "/home/sosna/.local/lib/python3.12/site-packages/graphviz/backend/execute.py", line 81, in run_check\n    raise ExecutableNotFound(cmd) from e\n', "graphviz.backend.execute.ExecutableNotFound: failed to execute PosixPath('dot'), make sure the Graphviz executables are on your systems' PATH\n"]

failed to execute PosixPath('dot'), make sure the Graphviz executables are on your systems' PATH
['Traceback (most recent call last):\n', '  File "/home/sosna/.local/lib/python3.12/site-packages/graphviz/backend/execute.py", line 78, in run_check\n    proc = subprocess.run(cmd, **kwargs)\n           ^^^^^^^^^^^^^^^^^^^^^^^^^^^^^\n', '  File "/usr/lib/python3.12/subprocess.py", line 548, in run\n    with Popen(*popenargs, **kwargs) as process:\n         ^^^^^^^^^^^^^^^^^^^^^^^^^^^\n', '  File "/usr/lib/python3.12/subprocess.py", line 1026, in __init__\n    self._execute_child(args, executable, preexec_fn, close_fds,\n', '  File "/usr/lib/python3.12/subprocess.py", line 1955, in _execute_child\n    raise child_exception_type(errno_num, err_msg, err_filename)\n', "FileNotFoundError: [Errno 2] No such file or directory: PosixPath('dot')\n", '\nThe above exception was the direct cause of the following exception:\n\n', 'Traceback (most recent call last):\n', '  File "/home/sosna/inzz/tempp/quad_cross/quad_learn_2.py", line 426, in learn\n    visualize.draw_net(config, winner, view=False, filename=os.path.join(\n', '  File "/home/sosna/inzz/tempp/quad_cross/visualize.py", line 182, in draw_net\n    dot.render(filename, view=view)\n', '  File "/home/sosna/.local/lib/python3.12/site-packages/graphviz/_tools.py", line 171, in wrapper\n    return func(*args, **kwargs)\n           ^^^^^^^^^^^^^^^^^^^^^\n', '  File "/home/sosna/.local/lib/python3.12/site-packages/graphviz/rendering.py", line 122, in render\n    rendered = self._render(*args, **kwargs)\n               ^^^^^^^^^^^^^^^^^^^^^^^^^^^^^\n', '  File "/home/sosna/.local/lib/python3.12/site-packages/graphviz/_tools.py", line 171, in wrapper\n    return func(*args, **kwargs)\n           ^^^^^^^^^^^^^^^^^^^^^\n', '  File "/home/sosna/.local/lib/python3.12/site-packages/graphviz/backend/rendering.py", line 326, in render\n    execute.run_check(cmd,\n', '  File "/home/sosna/.local/lib/python3.12/site-packages/graphviz/backend/execute.py", line 81, in run_check\n    raise ExecutableNotFound(cmd) from e\n', "graphviz.backend.execute.ExecutableNotFound: failed to execute PosixPath('dot'), make sure the Graphviz executables are on your systems' PATH\n"]

[Errno 32] Broken pipe
['multiprocessing.pool.RemoteTraceback: \n"""\nTraceback (most recent call last):\n  File "/home/sosna/inzz/tempp/quad_cross/quad_learn_2.py", line 250, in run_sim\n    result = sim(genome, config, rou)\n             ^^^^^^^^^^^^^^^^^^^^^^^^\n  File "/home/sosna/inzz/tempp/quad_cross/quad_learn_2.py", line 98, in sim\n    traci.start([sumoBinary,  "--no-warnings", "-c", filename,\n  File "/usr/lib/python3/dist-packages/traci/main.py", line 147, in start\n    result = init(sumoPort, numRetries, "localhost", label, sumoProcess, doSwitch, traceFile, traceGetters)\n             ^^^^^^^^^^^^^^^^^^^^^^^^^^^^^^^^^^^^^^^^^^^^^^^^^^^^^^^^^^^^^^^^^^^^^^^^^^^^^^^^^^^^^^^^^^^^^^\n  File "/usr/lib/python3/dist-packages/traci/main.py", line 119, in init\n    return con.getVersion()\n           ^^^^^^^^^^^^^^^^\n  File "/usr/lib/python3/dist-packages/traci/connection.py", line 381, in getVersion\n    result = self._sendCmd(command, None, None)\n             ^^^^^^^^^^^^^^^^^^^^^^^^^^^^^^^^^^\n  File "/usr/lib/python3/dist-packages/traci/connection.py", line 231, in _sendCmd\n    return self._sendExact()\n           ^^^^^^^^^^^^^^^^^\n  File "/usr/lib/python3/dist-packages/traci/connection.py", line 130, in _sendExact\n    self._socket.send(length + self._string)\nConnectionResetError: [Errno 104] Connection reset by peer\n\nDuring handling of the above exception, another exception occurred:\n\nTraceback (most recent call last):\n  File "/home/sosna/inzz/tempp/quad_cross/quad_learn_2.py", line 257, in run_sim\n    result = sim(genome, config, rou)\n             ^^^^^^^^^^^^^^^^^^^^^^^^\n  File "/home/sosna/inzz/tempp/quad_cross/quad_learn_2.py", line 98, in sim\n    traci.start([sumoBinary,  "--no-warnings", "-c", filename,\n  File "/usr/lib/python3/dist-packages/traci/main.py", line 139, in start\n    raise TraCIException("Connection \'%s\' is already active." % label)\ntraci.exceptions.TraCIException: Connection \'default\' is already active.\n\nDuring handling of the above exception, another exception occurred:\n\nTraceback (most recent call last):\n  File "/home/sosna/inzz/tempp/quad_cross/quad_learn_2.py", line 264, in run_sim\n    result = sim(genome, config, rou)\n             ^^^^^^^^^^^^^^^^^^^^^^^^\n  File "/home/sosna/inzz/tempp/quad_cross/quad_learn_2.py", line 98, in sim\n    traci.start([sumoBinary,  "--no-warnings", "-c", filename,\n  File "/usr/lib/python3/dist-packages/traci/main.py", line 139, in start\n    raise TraCIException("Connection \'%s\' is already active." % label)\ntraci.exceptions.TraCIException: Connection \'default\' is already active.\n\nDuring handling of the above exception, another exception occurred:\n\nTraceback (most recent call last):\n  File "/home/sosna/inzz/tempp/quad_cross/quad_learn_2.py", line 271, in run_sim\n    result = sim(genome, config, rou)\n             ^^^^^^^^^^^^^^^^^^^^^^^^\n  File "/home/sosna/inzz/tempp/quad_cross/quad_learn_2.py", line 98, in sim\n    traci.start([sumoBinary,  "--no-warnings", "-c", filename,\n  File "/usr/lib/python3/dist-packages/traci/main.py", line 139, in start\n    raise TraCIException("Connection \'%s\' is already active." % label)\ntraci.exceptions.TraCIException: Connection \'default\' is already active.\n\nDuring handling of the above exception, another exception occurred:\n\nTraceback (most recent call last):\n  File "/usr/lib/python3.12/multiprocessing/pool.py", line 125, in worker\n    result = (True, func(*args, **kwds))\n                    ^^^^^^^^^^^^^^^^^^^\n  File "/home/sosna/inzz/tempp/quad_cross/quad_learn_2.py", line 281, in eval_genome\n    fitness_1 = run_sim(genome, config, "_1")\n                ^^^^^^^^^^^^^^^^^^^^^^^^^^^^^\n  File "/home/sosna/inzz/tempp/quad_cross/quad_learn_2.py", line 277, in run_sim\n    traci.close()\n  File "/usr/lib/python3/dist-packages/traci/main.py", line 262, in close\n    connection.check().close(wait)\n  File "/usr/lib/python3/dist-packages/traci/connection.py", line 396, in close\n    self._sendCmd(tc.CMD_CLOSE, None, None)\n  File "/usr/lib/python3/dist-packages/traci/connection.py", line 231, in _sendCmd\n    return self._sendExact()\n           ^^^^^^^^^^^^^^^^^\n  File "/usr/lib/python3/dist-packages/traci/connection.py", line 130, in _sendExact\n    self._socket.send(length + self._string)\nBrokenPipeError: [Errno 32] Broken pipe\n"""\n', '\nThe above exception was the direct cause of the following exception:\n\n', 'Traceback (most recent call last):\n', '  File "/home/sosna/inzz/tempp/quad_cross/quad_learn_2.py", line 415, in learn\n    winner = pop.run(pe.evaluate, generations)\n             ^^^^^^^^^^^^^^^^^^^^^^^^^^^^^^^^^\n', '  File "/home/sosna/.local/lib/python3.12/site-packages/neat/population.py", line 89, in run\n    fitness_function(list(iteritems(self.population)), self.config)\n', '  File "/home/sosna/.local/lib/python3.12/site-packages/neat/parallel.py", line 30, in evaluate\n    genome.fitness = job.get(timeout=self.timeout)\n                     ^^^^^^^^^^^^^^^^^^^^^^^^^^^^^\n', '  File "/usr/lib/python3.12/multiprocessing/pool.py", line 774, in get\n    raise self._value\n', 'BrokenPipeError: [Errno 32] Broken pipe\n']

failed to execute PosixPath('dot'), make sure the Graphviz executables are on your systems' PATH
['Traceback (most recent call last):\n', '  File "/home/sosna/.local/lib/python3.12/site-packages/graphviz/backend/execute.py", line 78, in run_check\n    proc = subprocess.run(cmd, **kwargs)\n           ^^^^^^^^^^^^^^^^^^^^^^^^^^^^^\n', '  File "/usr/lib/python3.12/subprocess.py", line 548, in run\n    with Popen(*popenargs, **kwargs) as process:\n         ^^^^^^^^^^^^^^^^^^^^^^^^^^^\n', '  File "/usr/lib/python3.12/subprocess.py", line 1026, in __init__\n    self._execute_child(args, executable, preexec_fn, close_fds,\n', '  File "/usr/lib/python3.12/subprocess.py", line 1955, in _execute_child\n    raise child_exception_type(errno_num, err_msg, err_filename)\n', "FileNotFoundError: [Errno 2] No such file or directory: PosixPath('dot')\n", '\nThe above exception was the direct cause of the following exception:\n\n', 'Traceback (most recent call last):\n', '  File "/home/sosna/inzz/tempp/quad_cross/quad_learn_2.py", line 426, in learn\n    visualize.draw_net(config, winner, view=False, filename=os.path.join(\n', '  File "/home/sosna/inzz/tempp/quad_cross/visualize.py", line 182, in draw_net\n    dot.render(filename, view=view)\n', '  File "/home/sosna/.local/lib/python3.12/site-packages/graphviz/_tools.py", line 171, in wrapper\n    return func(*args, **kwargs)\n           ^^^^^^^^^^^^^^^^^^^^^\n', '  File "/home/sosna/.local/lib/python3.12/site-packages/graphviz/rendering.py", line 122, in render\n    rendered = self._render(*args, **kwargs)\n               ^^^^^^^^^^^^^^^^^^^^^^^^^^^^^\n', '  File "/home/sosna/.local/lib/python3.12/site-packages/graphviz/_tools.py", line 171, in wrapper\n    return func(*args, **kwargs)\n           ^^^^^^^^^^^^^^^^^^^^^\n', '  File "/home/sosna/.local/lib/python3.12/site-packages/graphviz/backend/rendering.py", line 326, in render\n    execute.run_check(cmd,\n', '  File "/home/sosna/.local/lib/python3.12/site-packages/graphviz/backend/execute.py", line 81, in run_check\n    raise ExecutableNotFound(cmd) from e\n', "graphviz.backend.execute.ExecutableNotFound: failed to execute PosixPath('dot'), make sure the Graphviz executables are on your systems' PATH\n"]

failed to execute PosixPath('dot'), make sure the Graphviz executables are on your systems' PATH
['Traceback (most recent call last):\n', '  File "/home/sosna/.local/lib/python3.12/site-packages/graphviz/backend/execute.py", line 78, in run_check\n    proc = subprocess.run(cmd, **kwargs)\n           ^^^^^^^^^^^^^^^^^^^^^^^^^^^^^\n', '  File "/usr/lib/python3.12/subprocess.py", line 548, in run\n    with Popen(*popenargs, **kwargs) as process:\n         ^^^^^^^^^^^^^^^^^^^^^^^^^^^\n', '  File "/usr/lib/python3.12/subprocess.py", line 1026, in __init__\n    self._execute_child(args, executable, preexec_fn, close_fds,\n', '  File "/usr/lib/python3.12/subprocess.py", line 1955, in _execute_child\n    raise child_exception_type(errno_num, err_msg, err_filename)\n', "FileNotFoundError: [Errno 2] No such file or directory: PosixPath('dot')\n", '\nThe above exception was the direct cause of the following exception:\n\n', 'Traceback (most recent call last):\n', '  File "/home/sosna/inzz/tempp/quad_cross/quad_learn_2.py", line 426, in learn\n    visualize.draw_net(config, winner, view=False, filename=os.path.join(\n', '  File "/home/sosna/inzz/tempp/quad_cross/visualize.py", line 182, in draw_net\n    dot.render(filename, view=view)\n', '  File "/home/sosna/.local/lib/python3.12/site-packages/graphviz/_tools.py", line 171, in wrapper\n    return func(*args, **kwargs)\n           ^^^^^^^^^^^^^^^^^^^^^\n', '  File "/home/sosna/.local/lib/python3.12/site-packages/graphviz/rendering.py", line 122, in render\n    rendered = self._render(*args, **kwargs)\n               ^^^^^^^^^^^^^^^^^^^^^^^^^^^^^\n', '  File "/home/sosna/.local/lib/python3.12/site-packages/graphviz/_tools.py", line 171, in wrapper\n    return func(*args, **kwargs)\n           ^^^^^^^^^^^^^^^^^^^^^\n', '  File "/home/sosna/.local/lib/python3.12/site-packages/graphviz/backend/rendering.py", line 326, in render\n    execute.run_check(cmd,\n', '  File "/home/sosna/.local/lib/python3.12/site-packages/graphviz/backend/execute.py", line 81, in run_check\n    raise ExecutableNotFound(cmd) from e\n', "graphviz.backend.execute.ExecutableNotFound: failed to execute PosixPath('dot'), make sure the Graphviz executables are on your systems' PATH\n"]

failed to execute PosixPath('dot'), make sure the Graphviz executables are on your systems' PATH
['Traceback (most recent call last):\n', '  File "/home/sosna/.local/lib/python3.12/site-packages/graphviz/backend/execute.py", line 78, in run_check\n    proc = subprocess.run(cmd, **kwargs)\n           ^^^^^^^^^^^^^^^^^^^^^^^^^^^^^\n', '  File "/usr/lib/python3.12/subprocess.py", line 548, in run\n    with Popen(*popenargs, **kwargs) as process:\n         ^^^^^^^^^^^^^^^^^^^^^^^^^^^\n', '  File "/usr/lib/python3.12/subprocess.py", line 1026, in __init__\n    self._execute_child(args, executable, preexec_fn, close_fds,\n', '  File "/usr/lib/python3.12/subprocess.py", line 1955, in _execute_child\n    raise child_exception_type(errno_num, err_msg, err_filename)\n', "FileNotFoundError: [Errno 2] No such file or directory: PosixPath('dot')\n", '\nThe above exception was the direct cause of the following exception:\n\n', 'Traceback (most recent call last):\n', '  File "/home/sosna/inzz/tempp/quad_cross/quad_learn_2.py", line 426, in learn\n    visualize.draw_net(config, winner, view=False, filename=os.path.join(\n', '  File "/home/sosna/inzz/tempp/quad_cross/visualize.py", line 182, in draw_net\n    dot.render(filename, view=view)\n', '  File "/home/sosna/.local/lib/python3.12/site-packages/graphviz/_tools.py", line 171, in wrapper\n    return func(*args, **kwargs)\n           ^^^^^^^^^^^^^^^^^^^^^\n', '  File "/home/sosna/.local/lib/python3.12/site-packages/graphviz/rendering.py", line 122, in render\n    rendered = self._render(*args, **kwargs)\n               ^^^^^^^^^^^^^^^^^^^^^^^^^^^^^\n', '  File "/home/sosna/.local/lib/python3.12/site-packages/graphviz/_tools.py", line 171, in wrapper\n    return func(*args, **kwargs)\n           ^^^^^^^^^^^^^^^^^^^^^\n', '  File "/home/sosna/.local/lib/python3.12/site-packages/graphviz/backend/rendering.py", line 326, in render\n    execute.run_check(cmd,\n', '  File "/home/sosna/.local/lib/python3.12/site-packages/graphviz/backend/execute.py", line 81, in run_check\n    raise ExecutableNotFound(cmd) from e\n', "graphviz.backend.execute.ExecutableNotFound: failed to execute PosixPath('dot'), make sure the Graphviz executables are on your systems' PATH\n"]

failed to execute PosixPath('dot'), make sure the Graphviz executables are on your systems' PATH
['Traceback (most recent call last):\n', '  File "/home/sosna/.local/lib/python3.12/site-packages/graphviz/backend/execute.py", line 78, in run_check\n    proc = subprocess.run(cmd, **kwargs)\n           ^^^^^^^^^^^^^^^^^^^^^^^^^^^^^\n', '  File "/usr/lib/python3.12/subprocess.py", line 548, in run\n    with Popen(*popenargs, **kwargs) as process:\n         ^^^^^^^^^^^^^^^^^^^^^^^^^^^\n', '  File "/usr/lib/python3.12/subprocess.py", line 1026, in __init__\n    self._execute_child(args, executable, preexec_fn, close_fds,\n', '  File "/usr/lib/python3.12/subprocess.py", line 1955, in _execute_child\n    raise child_exception_type(errno_num, err_msg, err_filename)\n', "FileNotFoundError: [Errno 2] No such file or directory: PosixPath('dot')\n", '\nThe above exception was the direct cause of the following exception:\n\n', 'Traceback (most recent call last):\n', '  File "/home/sosna/inzz/tempp/quad_cross/quad_learn_2.py", line 426, in learn\n    visualize.draw_net(config, winner, view=False, filename=os.path.join(\n', '  File "/home/sosna/inzz/tempp/quad_cross/visualize.py", line 182, in draw_net\n    dot.render(filename, view=view)\n', '  File "/home/sosna/.local/lib/python3.12/site-packages/graphviz/_tools.py", line 171, in wrapper\n    return func(*args, **kwargs)\n           ^^^^^^^^^^^^^^^^^^^^^\n', '  File "/home/sosna/.local/lib/python3.12/site-packages/graphviz/rendering.py", line 122, in render\n    rendered = self._render(*args, **kwargs)\n               ^^^^^^^^^^^^^^^^^^^^^^^^^^^^^\n', '  File "/home/sosna/.local/lib/python3.12/site-packages/graphviz/_tools.py", line 171, in wrapper\n    return func(*args, **kwargs)\n           ^^^^^^^^^^^^^^^^^^^^^\n', '  File "/home/sosna/.local/lib/python3.12/site-packages/graphviz/backend/rendering.py", line 326, in render\n    execute.run_check(cmd,\n', '  File "/home/sosna/.local/lib/python3.12/site-packages/graphviz/backend/execute.py", line 81, in run_check\n    raise ExecutableNotFound(cmd) from e\n', "graphviz.backend.execute.ExecutableNotFound: failed to execute PosixPath('dot'), make sure the Graphviz executables are on your systems' PATH\n"]

failed to execute PosixPath('dot'), make sure the Graphviz executables are on your systems' PATH
['Traceback (most recent call last):\n', '  File "/home/sosna/.local/lib/python3.12/site-packages/graphviz/backend/execute.py", line 78, in run_check\n    proc = subprocess.run(cmd, **kwargs)\n           ^^^^^^^^^^^^^^^^^^^^^^^^^^^^^\n', '  File "/usr/lib/python3.12/subprocess.py", line 548, in run\n    with Popen(*popenargs, **kwargs) as process:\n         ^^^^^^^^^^^^^^^^^^^^^^^^^^^\n', '  File "/usr/lib/python3.12/subprocess.py", line 1026, in __init__\n    self._execute_child(args, executable, preexec_fn, close_fds,\n', '  File "/usr/lib/python3.12/subprocess.py", line 1955, in _execute_child\n    raise child_exception_type(errno_num, err_msg, err_filename)\n', "FileNotFoundError: [Errno 2] No such file or directory: PosixPath('dot')\n", '\nThe above exception was the direct cause of the following exception:\n\n', 'Traceback (most recent call last):\n', '  File "/home/sosna/inzz/tempp/quad_cross/quad_learn_2.py", line 426, in learn\n    visualize.draw_net(config, winner, view=False, filename=os.path.join(\n', '  File "/home/sosna/inzz/tempp/quad_cross/visualize.py", line 182, in draw_net\n    dot.render(filename, view=view)\n', '  File "/home/sosna/.local/lib/python3.12/site-packages/graphviz/_tools.py", line 171, in wrapper\n    return func(*args, **kwargs)\n           ^^^^^^^^^^^^^^^^^^^^^\n', '  File "/home/sosna/.local/lib/python3.12/site-packages/graphviz/rendering.py", line 122, in render\n    rendered = self._render(*args, **kwargs)\n               ^^^^^^^^^^^^^^^^^^^^^^^^^^^^^\n', '  File "/home/sosna/.local/lib/python3.12/site-packages/graphviz/_tools.py", line 171, in wrapper\n    return func(*args, **kwargs)\n           ^^^^^^^^^^^^^^^^^^^^^\n', '  File "/home/sosna/.local/lib/python3.12/site-packages/graphviz/backend/rendering.py", line 326, in render\n    execute.run_check(cmd,\n', '  File "/home/sosna/.local/lib/python3.12/site-packages/graphviz/backend/execute.py", line 81, in run_check\n    raise ExecutableNotFound(cmd) from e\n', "graphviz.backend.execute.ExecutableNotFound: failed to execute PosixPath('dot'), make sure the Graphviz executables are on your systems' PATH\n"]

failed to execute PosixPath('dot'), make sure the Graphviz executables are on your systems' PATH
['Traceback (most recent call last):\n', '  File "/home/sosna/.local/lib/python3.12/site-packages/graphviz/backend/execute.py", line 78, in run_check\n    proc = subprocess.run(cmd, **kwargs)\n           ^^^^^^^^^^^^^^^^^^^^^^^^^^^^^\n', '  File "/usr/lib/python3.12/subprocess.py", line 548, in run\n    with Popen(*popenargs, **kwargs) as process:\n         ^^^^^^^^^^^^^^^^^^^^^^^^^^^\n', '  File "/usr/lib/python3.12/subprocess.py", line 1026, in __init__\n    self._execute_child(args, executable, preexec_fn, close_fds,\n', '  File "/usr/lib/python3.12/subprocess.py", line 1955, in _execute_child\n    raise child_exception_type(errno_num, err_msg, err_filename)\n', "FileNotFoundError: [Errno 2] No such file or directory: PosixPath('dot')\n", '\nThe above exception was the direct cause of the following exception:\n\n', 'Traceback (most recent call last):\n', '  File "/home/sosna/inzz/tempp/quad_cross/quad_learn_2.py", line 426, in learn\n    visualize.draw_net(config, winner, view=False, filename=os.path.join(\n', '  File "/home/sosna/inzz/tempp/quad_cross/visualize.py", line 182, in draw_net\n    dot.render(filename, view=view)\n', '  File "/home/sosna/.local/lib/python3.12/site-packages/graphviz/_tools.py", line 171, in wrapper\n    return func(*args, **kwargs)\n           ^^^^^^^^^^^^^^^^^^^^^\n', '  File "/home/sosna/.local/lib/python3.12/site-packages/graphviz/rendering.py", line 122, in render\n    rendered = self._render(*args, **kwargs)\n               ^^^^^^^^^^^^^^^^^^^^^^^^^^^^^\n', '  File "/home/sosna/.local/lib/python3.12/site-packages/graphviz/_tools.py", line 171, in wrapper\n    return func(*args, **kwargs)\n           ^^^^^^^^^^^^^^^^^^^^^\n', '  File "/home/sosna/.local/lib/python3.12/site-packages/graphviz/backend/rendering.py", line 326, in render\n    execute.run_check(cmd,\n', '  File "/home/sosna/.local/lib/python3.12/site-packages/graphviz/backend/execute.py", line 81, in run_check\n    raise ExecutableNotFound(cmd) from e\n', "graphviz.backend.execute.ExecutableNotFound: failed to execute PosixPath('dot'), make sure the Graphviz executables are on your systems' PATH\n"]

failed to execute PosixPath('dot'), make sure the Graphviz executables are on your systems' PATH
['Traceback (most recent call last):\n', '  File "/home/sosna/.local/lib/python3.12/site-packages/graphviz/backend/execute.py", line 78, in run_check\n    proc = subprocess.run(cmd, **kwargs)\n           ^^^^^^^^^^^^^^^^^^^^^^^^^^^^^\n', '  File "/usr/lib/python3.12/subprocess.py", line 548, in run\n    with Popen(*popenargs, **kwargs) as process:\n         ^^^^^^^^^^^^^^^^^^^^^^^^^^^\n', '  File "/usr/lib/python3.12/subprocess.py", line 1026, in __init__\n    self._execute_child(args, executable, preexec_fn, close_fds,\n', '  File "/usr/lib/python3.12/subprocess.py", line 1955, in _execute_child\n    raise child_exception_type(errno_num, err_msg, err_filename)\n', "FileNotFoundError: [Errno 2] No such file or directory: PosixPath('dot')\n", '\nThe above exception was the direct cause of the following exception:\n\n', 'Traceback (most recent call last):\n', '  File "/home/sosna/inzz/tempp/quad_cross/quad_learn_2.py", line 426, in learn\n    visualize.draw_net(config, winner, view=False, filename=os.path.join(\n', '  File "/home/sosna/inzz/tempp/quad_cross/visualize.py", line 182, in draw_net\n    dot.render(filename, view=view)\n', '  File "/home/sosna/.local/lib/python3.12/site-packages/graphviz/_tools.py", line 171, in wrapper\n    return func(*args, **kwargs)\n           ^^^^^^^^^^^^^^^^^^^^^\n', '  File "/home/sosna/.local/lib/python3.12/site-packages/graphviz/rendering.py", line 122, in render\n    rendered = self._render(*args, **kwargs)\n               ^^^^^^^^^^^^^^^^^^^^^^^^^^^^^\n', '  File "/home/sosna/.local/lib/python3.12/site-packages/graphviz/_tools.py", line 171, in wrapper\n    return func(*args, **kwargs)\n           ^^^^^^^^^^^^^^^^^^^^^\n', '  File "/home/sosna/.local/lib/python3.12/site-packages/graphviz/backend/rendering.py", line 326, in render\n    execute.run_check(cmd,\n', '  File "/home/sosna/.local/lib/python3.12/site-packages/graphviz/backend/execute.py", line 81, in run_check\n    raise ExecutableNotFound(cmd) from e\n', "graphviz.backend.execute.ExecutableNotFound: failed to execute PosixPath('dot'), make sure the Graphviz executables are on your systems' PATH\n"]

