-1402.1,1404,VehicleNumberAndHaltingNumber,1002_pop_180_data_VehicleNumberAndHaltingNumber,0.01,2,1.5,partial_direct 1,0.6,1,0.3,0.9,0.4,0.9,0.03,0.5,0.1,3.3333333333333335,10,2,0.3,0.1,2.0,10,1,0.7,0.1,10.0,20,2,0.7,0.5,11,15,2,3,0.66,13
-1417.2,1408,VehicleNumberAndHaltingNumber,1030_pop_180_data_VehicleNumberAndHaltingNumber,0.1,2,1,partial_direct 1,0.6,0.6,0.5,0.9,0.6,0.9,0,0.5,0.1,10.0,50,4,0.7,0.5,1.0,5,2,0.5,0.2,2.0,20,4,0.5,0.5,13,25,2,1,0.5,7
-1369.79,1198,VehicleNumberAndHaltingNumber,1031_pop_180_data_VehicleNumberAndHaltingNumber,0.1,1.7,1.25,partial_direct 1,0.2,1,0.3,0.99,0.6,0.9,0.03,0,0,5.0,50,2,0.3,0.3,0.5,1,0.5,0.3,0.2,6.666666666666667,20,1,0.7,0.3,12,15,2,2,0.33,9
-1413.28,1387,VehicleNumberAndHaltingNumber,1032_pop_180_data_VehicleNumberAndHaltingNumber,0.1,2,1.05,partial_direct 0,0.4,0.4,0.8,1.1,0.3,0.99,0.5,0.03,0.01,10.0,50,1,0.7,0.5,0.1,1,4,0.7,0.5,0.1,1,4,0.9,0.5,10,15,4,2,0.5,13
[Errno 32] Broken pipe
['multiprocessing.pool.RemoteTraceback: \n"""\nTraceback (most recent call last):\n  File "/home/sosna/inzz/quad_cross/quad_learn_2.py", line 250, in run_sim\n    result = sim(genome, config, rou)\n             ^^^^^^^^^^^^^^^^^^^^^^^^\n  File "/home/sosna/inzz/quad_cross/quad_learn_2.py", line 98, in sim\n    traci.start([sumoBinary,  "--no-warnings", "-c", filename,\n  File "/usr/lib/python3/dist-packages/traci/main.py", line 147, in start\n    result = init(sumoPort, numRetries, "localhost", label, sumoProcess, doSwitch, traceFile, traceGetters)\n             ^^^^^^^^^^^^^^^^^^^^^^^^^^^^^^^^^^^^^^^^^^^^^^^^^^^^^^^^^^^^^^^^^^^^^^^^^^^^^^^^^^^^^^^^^^^^^^\n  File "/usr/lib/python3/dist-packages/traci/main.py", line 119, in init\n    return con.getVersion()\n           ^^^^^^^^^^^^^^^^\n  File "/usr/lib/python3/dist-packages/traci/connection.py", line 381, in getVersion\n    result = self._sendCmd(command, None, None)\n             ^^^^^^^^^^^^^^^^^^^^^^^^^^^^^^^^^^\n  File "/usr/lib/python3/dist-packages/traci/connection.py", line 231, in _sendCmd\n    return self._sendExact()\n           ^^^^^^^^^^^^^^^^^\n  File "/usr/lib/python3/dist-packages/traci/connection.py", line 130, in _sendExact\n    self._socket.send(length + self._string)\nConnectionResetError: [Errno 104] Connection reset by peer\n\nDuring handling of the above exception, another exception occurred:\n\nTraceback (most recent call last):\n  File "/home/sosna/inzz/quad_cross/quad_learn_2.py", line 257, in run_sim\n    result = sim(genome, config, rou)\n             ^^^^^^^^^^^^^^^^^^^^^^^^\n  File "/home/sosna/inzz/quad_cross/quad_learn_2.py", line 98, in sim\n    traci.start([sumoBinary,  "--no-warnings", "-c", filename,\n  File "/usr/lib/python3/dist-packages/traci/main.py", line 139, in start\n    raise TraCIException("Connection \'%s\' is already active." % label)\ntraci.exceptions.TraCIException: Connection \'default\' is already active.\n\nDuring handling of the above exception, another exception occurred:\n\nTraceback (most recent call last):\n  File "/home/sosna/inzz/quad_cross/quad_learn_2.py", line 264, in run_sim\n    result = sim(genome, config, rou)\n             ^^^^^^^^^^^^^^^^^^^^^^^^\n  File "/home/sosna/inzz/quad_cross/quad_learn_2.py", line 98, in sim\n    traci.start([sumoBinary,  "--no-warnings", "-c", filename,\n  File "/usr/lib/python3/dist-packages/traci/main.py", line 139, in start\n    raise TraCIException("Connection \'%s\' is already active." % label)\ntraci.exceptions.TraCIException: Connection \'default\' is already active.\n\nDuring handling of the above exception, another exception occurred:\n\nTraceback (most recent call last):\n  File "/home/sosna/inzz/quad_cross/quad_learn_2.py", line 271, in run_sim\n    result = sim(genome, config, rou)\n             ^^^^^^^^^^^^^^^^^^^^^^^^\n  File "/home/sosna/inzz/quad_cross/quad_learn_2.py", line 98, in sim\n    traci.start([sumoBinary,  "--no-warnings", "-c", filename,\n  File "/usr/lib/python3/dist-packages/traci/main.py", line 139, in start\n    raise TraCIException("Connection \'%s\' is already active." % label)\ntraci.exceptions.TraCIException: Connection \'default\' is already active.\n\nDuring handling of the above exception, another exception occurred:\n\nTraceback (most recent call last):\n  File "/usr/lib/python3.12/multiprocessing/pool.py", line 125, in worker\n    result = (True, func(*args, **kwds))\n                    ^^^^^^^^^^^^^^^^^^^\n  File "/home/sosna/inzz/quad_cross/quad_learn_2.py", line 281, in eval_genome\n    fitness_1 = run_sim(genome, config, "_1")\n                ^^^^^^^^^^^^^^^^^^^^^^^^^^^^^\n  File "/home/sosna/inzz/quad_cross/quad_learn_2.py", line 277, in run_sim\n    traci.close()\n  File "/usr/lib/python3/dist-packages/traci/main.py", line 262, in close\n    connection.check().close(wait)\n  File "/usr/lib/python3/dist-packages/traci/connection.py", line 396, in close\n    self._sendCmd(tc.CMD_CLOSE, None, None)\n  File "/usr/lib/python3/dist-packages/traci/connection.py", line 231, in _sendCmd\n    return self._sendExact()\n           ^^^^^^^^^^^^^^^^^\n  File "/usr/lib/python3/dist-packages/traci/connection.py", line 130, in _sendExact\n    self._socket.send(length + self._string)\nBrokenPipeError: [Errno 32] Broken pipe\n"""\n', '\nThe above exception was the direct cause of the following exception:\n\n', 'Traceback (most recent call last):\n', '  File "/home/sosna/inzz/quad_cross/quad_learn_2.py", line 415, in learn\n    winner = pop.run(pe.evaluate, generations)\n             ^^^^^^^^^^^^^^^^^^^^^^^^^^^^^^^^^\n', '  File "/home/sosna/.local/lib/python3.12/site-packages/neat/population.py", line 89, in run\n    fitness_function(list(iteritems(self.population)), self.config)\n', '  File "/home/sosna/.local/lib/python3.12/site-packages/neat/parallel.py", line 30, in evaluate\n    genome.fitness = job.get(timeout=self.timeout)\n                     ^^^^^^^^^^^^^^^^^^^^^^^^^^^^^\n', '  File "/usr/lib/python3.12/multiprocessing/pool.py", line 774, in get\n    raise self._value\n', 'BrokenPipeError: [Errno 32] Broken pipe\n']

-1369.79,1210,VehicleNumberAndHaltingNumber,1034_pop_180_data_VehicleNumberAndHaltingNumber,0.1,1.7,1,partial_direct 0.5,0.8,0.6,0.3,1.1,0.6,1.1,0.03,0.03,0,6.666666666666667,10,2,0.5,0.3,0.5,1,2,0.3,0.2,3.3333333333333335,10,0.5,0.5,0.7,14,15,4,3,0.66,7
[Errno 32] Broken pipe
['multiprocessing.pool.RemoteTraceback: \n"""\nTraceback (most recent call last):\n  File "/home/sosna/inzz/quad_cross/quad_learn_2.py", line 250, in run_sim\n    result = sim(genome, config, rou)\n             ^^^^^^^^^^^^^^^^^^^^^^^^\n  File "/home/sosna/inzz/quad_cross/quad_learn_2.py", line 98, in sim\n    traci.start([sumoBinary,  "--no-warnings", "-c", filename,\n  File "/usr/lib/python3/dist-packages/traci/main.py", line 147, in start\n    result = init(sumoPort, numRetries, "localhost", label, sumoProcess, doSwitch, traceFile, traceGetters)\n             ^^^^^^^^^^^^^^^^^^^^^^^^^^^^^^^^^^^^^^^^^^^^^^^^^^^^^^^^^^^^^^^^^^^^^^^^^^^^^^^^^^^^^^^^^^^^^^\n  File "/usr/lib/python3/dist-packages/traci/main.py", line 119, in init\n    return con.getVersion()\n           ^^^^^^^^^^^^^^^^\n  File "/usr/lib/python3/dist-packages/traci/connection.py", line 381, in getVersion\n    result = self._sendCmd(command, None, None)\n             ^^^^^^^^^^^^^^^^^^^^^^^^^^^^^^^^^^\n  File "/usr/lib/python3/dist-packages/traci/connection.py", line 231, in _sendCmd\n    return self._sendExact()\n           ^^^^^^^^^^^^^^^^^\n  File "/usr/lib/python3/dist-packages/traci/connection.py", line 130, in _sendExact\n    self._socket.send(length + self._string)\nConnectionResetError: [Errno 104] Connection reset by peer\n\nDuring handling of the above exception, another exception occurred:\n\nTraceback (most recent call last):\n  File "/home/sosna/inzz/quad_cross/quad_learn_2.py", line 257, in run_sim\n    result = sim(genome, config, rou)\n             ^^^^^^^^^^^^^^^^^^^^^^^^\n  File "/home/sosna/inzz/quad_cross/quad_learn_2.py", line 98, in sim\n    traci.start([sumoBinary,  "--no-warnings", "-c", filename,\n  File "/usr/lib/python3/dist-packages/traci/main.py", line 139, in start\n    raise TraCIException("Connection \'%s\' is already active." % label)\ntraci.exceptions.TraCIException: Connection \'default\' is already active.\n\nDuring handling of the above exception, another exception occurred:\n\nTraceback (most recent call last):\n  File "/home/sosna/inzz/quad_cross/quad_learn_2.py", line 264, in run_sim\n    result = sim(genome, config, rou)\n             ^^^^^^^^^^^^^^^^^^^^^^^^\n  File "/home/sosna/inzz/quad_cross/quad_learn_2.py", line 98, in sim\n    traci.start([sumoBinary,  "--no-warnings", "-c", filename,\n  File "/usr/lib/python3/dist-packages/traci/main.py", line 139, in start\n    raise TraCIException("Connection \'%s\' is already active." % label)\ntraci.exceptions.TraCIException: Connection \'default\' is already active.\n\nDuring handling of the above exception, another exception occurred:\n\nTraceback (most recent call last):\n  File "/home/sosna/inzz/quad_cross/quad_learn_2.py", line 271, in run_sim\n    result = sim(genome, config, rou)\n             ^^^^^^^^^^^^^^^^^^^^^^^^\n  File "/home/sosna/inzz/quad_cross/quad_learn_2.py", line 98, in sim\n    traci.start([sumoBinary,  "--no-warnings", "-c", filename,\n  File "/usr/lib/python3/dist-packages/traci/main.py", line 139, in start\n    raise TraCIException("Connection \'%s\' is already active." % label)\ntraci.exceptions.TraCIException: Connection \'default\' is already active.\n\nDuring handling of the above exception, another exception occurred:\n\nTraceback (most recent call last):\n  File "/usr/lib/python3.12/multiprocessing/pool.py", line 125, in worker\n    result = (True, func(*args, **kwds))\n                    ^^^^^^^^^^^^^^^^^^^\n  File "/home/sosna/inzz/quad_cross/quad_learn_2.py", line 281, in eval_genome\n    fitness_1 = run_sim(genome, config, "_1")\n                ^^^^^^^^^^^^^^^^^^^^^^^^^^^^^\n  File "/home/sosna/inzz/quad_cross/quad_learn_2.py", line 277, in run_sim\n    traci.close()\n  File "/usr/lib/python3/dist-packages/traci/main.py", line 262, in close\n    connection.check().close(wait)\n  File "/usr/lib/python3/dist-packages/traci/connection.py", line 396, in close\n    self._sendCmd(tc.CMD_CLOSE, None, None)\n  File "/usr/lib/python3/dist-packages/traci/connection.py", line 231, in _sendCmd\n    return self._sendExact()\n           ^^^^^^^^^^^^^^^^^\n  File "/usr/lib/python3/dist-packages/traci/connection.py", line 130, in _sendExact\n    self._socket.send(length + self._string)\nBrokenPipeError: [Errno 32] Broken pipe\n"""\n', '\nThe above exception was the direct cause of the following exception:\n\n', 'Traceback (most recent call last):\n', '  File "/home/sosna/inzz/quad_cross/quad_learn_2.py", line 415, in learn\n    winner = pop.run(pe.evaluate, generations)\n             ^^^^^^^^^^^^^^^^^^^^^^^^^^^^^^^^^\n', '  File "/home/sosna/.local/lib/python3.12/site-packages/neat/population.py", line 89, in run\n    fitness_function(list(iteritems(self.population)), self.config)\n', '  File "/home/sosna/.local/lib/python3.12/site-packages/neat/parallel.py", line 30, in evaluate\n    genome.fitness = job.get(timeout=self.timeout)\n                     ^^^^^^^^^^^^^^^^^^^^^^^^^^^^^\n', '  File "/usr/lib/python3.12/multiprocessing/pool.py", line 774, in get\n    raise self._value\n', 'BrokenPipeError: [Errno 32] Broken pipe\n']

