[Errno 32] Broken pipe
['multiprocessing.pool.RemoteTraceback: \n"""\nTraceback (most recent call last):\n  File "/home/ubuntu/Desktop/inzz/quad_cross/quad_learn_3.py", line 250, in run_sim\n    result = sim(genome, config, rou)\n  File "/home/ubuntu/Desktop/inzz/quad_cross/quad_learn_3.py", line 98, in sim\n    traci.start([sumoBinary,  "--no-warnings", "-c", filename,\n  File "/home/ubuntu/.local/lib/python3.10/site-packages/traci/main.py", line 147, in start\n    result = init(sumoPort, numRetries, "localhost", label, sumoProcess, doSwitch, traceFile, traceGetters)\n  File "/home/ubuntu/.local/lib/python3.10/site-packages/traci/main.py", line 119, in init\n    return con.getVersion()\n  File "/home/ubuntu/.local/lib/python3.10/site-packages/traci/connection.py", line 381, in getVersion\n    result = self._sendCmd(command, None, None)\n  File "/home/ubuntu/.local/lib/python3.10/site-packages/traci/connection.py", line 231, in _sendCmd\n    return self._sendExact()\n  File "/home/ubuntu/.local/lib/python3.10/site-packages/traci/connection.py", line 130, in _sendExact\n    self._socket.send(length + self._string)\nConnectionResetError: [Errno 104] Connection reset by peer\n\nDuring handling of the above exception, another exception occurred:\n\nTraceback (most recent call last):\n  File "/home/ubuntu/Desktop/inzz/quad_cross/quad_learn_3.py", line 257, in run_sim\n    result = sim(genome, config, rou)\n  File "/home/ubuntu/Desktop/inzz/quad_cross/quad_learn_3.py", line 98, in sim\n    traci.start([sumoBinary,  "--no-warnings", "-c", filename,\n  File "/home/ubuntu/.local/lib/python3.10/site-packages/traci/main.py", line 139, in start\n    raise TraCIException("Connection \'%s\' is already active." % label)\ntraci.exceptions.TraCIException: Connection \'default\' is already active.\n\nDuring handling of the above exception, another exception occurred:\n\nTraceback (most recent call last):\n  File "/home/ubuntu/Desktop/inzz/quad_cross/quad_learn_3.py", line 264, in run_sim\n    result = sim(genome, config, rou)\n  File "/home/ubuntu/Desktop/inzz/quad_cross/quad_learn_3.py", line 98, in sim\n    traci.start([sumoBinary,  "--no-warnings", "-c", filename,\n  File "/home/ubuntu/.local/lib/python3.10/site-packages/traci/main.py", line 139, in start\n    raise TraCIException("Connection \'%s\' is already active." % label)\ntraci.exceptions.TraCIException: Connection \'default\' is already active.\n\nDuring handling of the above exception, another exception occurred:\n\nTraceback (most recent call last):\n  File "/home/ubuntu/Desktop/inzz/quad_cross/quad_learn_3.py", line 271, in run_sim\n    result = sim(genome, config, rou)\n  File "/home/ubuntu/Desktop/inzz/quad_cross/quad_learn_3.py", line 98, in sim\n    traci.start([sumoBinary,  "--no-warnings", "-c", filename,\n  File "/home/ubuntu/.local/lib/python3.10/site-packages/traci/main.py", line 139, in start\n    raise TraCIException("Connection \'%s\' is already active." % label)\ntraci.exceptions.TraCIException: Connection \'default\' is already active.\n\nDuring handling of the above exception, another exception occurred:\n\nTraceback (most recent call last):\n  File "/usr/lib/python3.10/multiprocessing/pool.py", line 125, in worker\n    result = (True, func(*args, **kwds))\n  File "/home/ubuntu/Desktop/inzz/quad_cross/quad_learn_3.py", line 281, in eval_genome\n    fitness_1 = run_sim(genome, config, "_1")\n  File "/home/ubuntu/Desktop/inzz/quad_cross/quad_learn_3.py", line 277, in run_sim\n    traci.close()\n  File "/home/ubuntu/.local/lib/python3.10/site-packages/traci/main.py", line 262, in close\n    connection.check().close(wait)\n  File "/home/ubuntu/.local/lib/python3.10/site-packages/traci/connection.py", line 396, in close\n    self._sendCmd(tc.CMD_CLOSE, None, None)\n  File "/home/ubuntu/.local/lib/python3.10/site-packages/traci/connection.py", line 231, in _sendCmd\n    return self._sendExact()\n  File "/home/ubuntu/.local/lib/python3.10/site-packages/traci/connection.py", line 130, in _sendExact\n    self._socket.send(length + self._string)\nBrokenPipeError: [Errno 32] Broken pipe\n"""\n', '\nThe above exception was the direct cause of the following exception:\n\n', 'Traceback (most recent call last):\n', '  File "/home/ubuntu/Desktop/inzz/quad_cross/quad_learn_3.py", line 415, in learn\n    winner = pop.run(pe.evaluate, generations)\n', '  File "/home/ubuntu/.local/lib/python3.10/site-packages/neat/population.py", line 89, in run\n    fitness_function(list(iteritems(self.population)), self.config)\n', '  File "/home/ubuntu/.local/lib/python3.10/site-packages/neat/parallel.py", line 30, in evaluate\n    genome.fitness = job.get(timeout=self.timeout)\n', '  File "/usr/lib/python3.10/multiprocessing/pool.py", line 774, in get\n    raise self._value\n', 'BrokenPipeError: [Errno 32] Broken pipe\n']

-979.20222,6186,VehicleNumberAndHaltingNumber,132_pop_200_data_VehicleNumberAndHaltingNumber,0.05,1.6,1.3,partial_direct 0.5,0.4,0.8,0.5,0.45,0.3,0.33,0.1,0.5,0.3,10.0,100,2,0.6,0.3,4.666666666666667,7,2,0.7,0.2,1.0,10,2,0.91,0.5,12.5,13,4,3,0.5,8
[Errno 32] Broken pipe
['multiprocessing.pool.RemoteTraceback: \n
"""\nTraceback (most recent call last):\n
  File "/home/ubuntu/Desktop/inzz/quad_cross/quad_learn_3.py", line 250, in run_sim\n
    result = sim(genome, config, rou)\n
  File "/home/ubuntu/Desktop/inzz/quad_cross/quad_learn_3.py", line 98, in sim\n
    traci.start([sumoBinary,  "--no-warnings", "-c", filename,\n
  File "/home/ubuntu/.local/lib/python3.10/site-packages/traci/main.py", line 147, in start\n
    result = init(sumoPort, numRetries, "localhost", label, sumoProcess, doSwitch, traceFile, traceGetters)\n
  File "/home/ubuntu/.local/lib/python3.10/site-packages/traci/main.py", line 119, in init\n
    return con.getVersion()\n  File "/home/ubuntu/.local/lib/python3.10/site-packages/traci/connection.py", line 381, in getVersion\n
    result = self._sendCmd(command, None, None)\n
  File "/home/ubuntu/.local/lib/python3.10/site-packages/traci/connection.py", line 231, in _sendCmd\n
    return self._sendExact()\n
  File "/home/ubuntu/.local/lib/python3.10/site-packages/traci/connection.py", line 130, in _sendExact\n
    self._socket.send(length + self._string)\n
ConnectionResetError: [Errno 104] Connection reset by peer\n\n
During handling of the above exception, another exception occurred:\n\n
Traceback (most recent call last):\n
  File "/home/ubuntu/Desktop/inzz/quad_cross/quad_learn_3.py", line 257, in run_sim\n
    result = sim(genome, config, rou)\n
  File "/home/ubuntu/Desktop/inzz/quad_cross/quad_learn_3.py", line 98, in sim\n
    traci.start([sumoBinary,  "--no-warnings", "-c", filename,\n
  File "/home/ubuntu/.local/lib/python3.10/site-packages/traci/main.py", line 139, in start\n
    raise TraCIException("Connection \'%s\' is already active." % label)\n
traci.exceptions.TraCIException: Connection \'default\' is already active.\n\n
During handling of the above exception, another exception occurred:\n\n
Traceback (most recent call last):\n  File "/home/ubuntu/Desktop/inzz/quad_cross/quad_learn_3.py", line 264, in run_sim\n
    result = sim(genome, config, rou)\n
  File "/home/ubuntu/Desktop/inzz/quad_cross/quad_learn_3.py", line 98, in sim\n
    traci.start([sumoBinary,  "--no-warnings", "-c", filename,\n
  File "/home/ubuntu/.local/lib/python3.10/site-packages/traci/main.py", line 139, in start\n
    raise TraCIException("Connection \'%s\' is already active." % label)\n
traci.exceptions.TraCIException: Connection \'default\' is already active.\n\n
During handling of the above exception, another exception occurred:\n\nTraceback (most recent call last):\n
  File "/home/ubuntu/Desktop/inzz/quad_cross/quad_learn_3.py", line 271, in run_sim\n
    result = sim(genome, config, rou)\n  File "/home/ubuntu/Desktop/inzz/quad_cross/quad_learn_3.py", line 98, in sim\n
    traci.start([sumoBinary,  "--no-warnings", "-c", filename,\n
  File "/home/ubuntu/.local/lib/python3.10/site-packages/traci/main.py", line 139, in start\n
    raise TraCIException("Connection \'%s\' is already active." % label)\n
traci.exceptions.TraCIException: Connection \'default\' is already active.\n\n
During handling of the above exception, another exception occurred:\n\nTraceback (most recent call last):\n
  File "/usr/lib/python3.10/multiprocessing/pool.py", line 125, in worker\n
    result = (True, func(*args, **kwds))\n
  File "/home/ubuntu/Desktop/inzz/quad_cross/quad_learn_3.py", line 281, in eval_genome\n
    fitness_1 = run_sim(genome, config, "_1")\n
  File "/home/ubuntu/Desktop/inzz/quad_cross/quad_learn_3.py", line 277, in run_sim\n
    traci.close()\n
  File "/home/ubuntu/.local/lib/python3.10/site-packages/traci/main.py", line 262, in close\n
    connection.check().close(wait)\n
  File "/home/ubuntu/.local/lib/python3.10/site-packages/traci/connection.py", line 396, in close\n
    self._sendCmd(tc.CMD_CLOSE, None, None)\n
  File "/home/ubuntu/.local/lib/python3.10/site-packages/traci/connection.py", line 231, in _sendCmd\n
    return self._sendExact()\n
  File "/home/ubuntu/.local/lib/python3.10/site-packages/traci/connection.py", line 130, in _sendExact\n
    self._socket.send(length + self._string)\n
BrokenPipeError: [Errno 32] Broken pipe\n"""\n
', '\nThe above exception was the direct cause of the following exception:\n\n
', 'Traceback (most recent call last):\n
', '  File "/home/ubuntu/Desktop/inzz/quad_cross/quad_learn_3.py", line 415, in learn\n
    winner = pop.run(pe.evaluate, generations)\n
', '  File "/home/ubuntu/.local/lib/python3.10/site-packages/neat/population.py", line 89, in run\n
    fitness_function(list(iteritems(self.population)), self.config)\n
', '  File "/home/ubuntu/.local/lib/python3.10/site-packages/neat/parallel.py", line 30, in evaluate\n
    genome.fitness = job.get(timeout=self.timeout)\n
', '  File "/usr/lib/python3.10/multiprocessing/pool.py", line 774, in get\n
    raise self._value\n', 'BrokenPipeError: [Errno 32] Broken pipe\n']

-1369.79,5409,VehicleNumberAndHaltingNumber,134_pop_200_data_VehicleNumberAndHaltingNumber,0.05,1.4,1.4,partial_direct 0,0.5,1.15,0.8,0.7200000000000001,0.3,0.27,0.1,0.7,0.1,40.0,200,1,0.5,0.3,2.5,5,2,0.7,0.2,4.0,20,1,0.84,0.6,11.5,13,4,3,0.5,11
-1369.79,6083,VehicleNumberAndHaltingNumber,135_pop_200_data_VehicleNumberAndHaltingNumber,0.05,1.6,1.6,partial_direct 1,0.2,1.3,0.3,0.297,0.5,0.55,0.1,0.3,0.05,20.0,200,2,0.6,0.1,2.5,5,1,0.8,0.2,3.3333333333333335,10,1,0.84,0.6,11.5,21,4,2,0.4,11
